Workbook

Sheet 图表
A1: =TODAY() -> 46096
B2: 持仓情况 | C2: 入手价格 | D2: 入手时间 | E2: 持仓天数 | F2: 目前价格 | G2: 盈亏
B3: 电棍 | C3: 3980 | D3: 46044 | E3: =-(D3-$A$1) -> 52 | F3: =IFERROR(_xlfn.XLOOKUP(B3,弹性!B:B,弹性!D:D),"") -> 5100 | G3: =F3-C3 -> 1120
B4: 龙骑 | C4: 1898 | D4: 46035 | E4: =-(D4-$A$1) -> 61 | F4: =IFERROR(_xlfn.XLOOKUP(B4,弹性!B:B,弹性!D:D),"") -> 1890 | G4: =F4-C4 -> -8
B5: 斧王 | C5: 1800 | D5: 46044 | E5: =-(D5-$A$1) -> 52 | F5: =IFERROR(_xlfn.XLOOKUP(B5,弹性!B:B,弹性!D:D),"") -> 1819 | G5: =F5-C5 -> 19
B6: 海民 | C6: 1995 | D6: 46058 | E6: =-(D6-$A$1) -> 38 | F6: =IFERROR(_xlfn.XLOOKUP(B6,弹性!B:B,弹性!D:D),"") -> 1800 | G6: =F6-C6 -> -195
B7: 先知 | C7: 2535 | D7: 46058 | E7: =-(D7-$A$1) -> 38 | F7: =IFERROR(_xlfn.XLOOKUP(B7,弹性!B:B,弹性!D:D),"") -> 2595 | G7: =F7-C7 -> 60
B9: 仓位 | C9: =SUM(C3:C7) -> 12208
B10: 目前市场价 | C10: =SUM(F3:F7) -> 13204
B11: 总盈亏 | C11: =C10-C9 -> 996
B12: 收益 | C12: =C11/C9 -> 0.081585845
B13: 月收益 | C13: =C12/(AVERAGE(E3:E5)/30) -> 0.04450137

Sheet 弹性
B2: 英雄 | C2: 部位 | D2: 目前价格 | E2: 目前数量 | F2: 上期价格 | G2: 上期数量 | H2: 最低价格 | I2: 最低数量 | J2: 最高价格 | K2: 最高数量 | L2: 波动 | M2: 价格同比 | N2: 数量同比 | O2: 同比弹性 | P2: 同比评价 | Q2: 价格环比 | R2: 数量环比 | S2: 环比弹性 | T2: 环比评价 | U2: 最低
B3: 电棍 | C3: 头 | D3: {=_xlfn.LET(_xlpm.key,$B3&"|"&$C3,_xlpm.kdb,价格数据库!$A$3:$A$2000&"|"&价格数据库!$B$3:$B$2000,_xlpm.r,_xlfn.XMATCH(_xlpm.key,_xlpm.kdb,0),_xlpm.row,INDEX(价格数据库!$C$3:$ZZ$2000,_xlpm.r,0),_xlpm.n,INT(COLUMNS(_xlpm.row)/2),_xlpm.p,_xlfn.CHOOSECOLS(_xlpm.row,_xlfn.SEQUENCE(,_xlpm.n,1,2)),IFERROR(LOOKUP(2,1/(_xlpm.p<>""),_xlpm.p),""))} -> 5100 | E3: {=_xlfn.LET(_xlpm.key,$B3&"|"&$C3,_xlpm.kdb,价格数据库!$A$3:$A$2000&"|"&价格数据库!$B$3:$B$2000,_xlpm.r,_xlfn.XMATCH(_xlpm.key,_xlpm.kdb,0),_xlpm.row,INDEX(价格数据库!$C$3:$ZZ$2000,_xlpm.r,0),_xlpm.n,INT(COLUMNS(_xlpm.row)/2),_xlpm.p,_xlfn.CHOOSECOLS(_xlpm.row,_xlfn.SEQUENCE(,_xlpm.n,1,2)),_xlpm.q,_xlfn.CHOOSECOLS(_xlpm.row,_xlfn.SEQUENCE(,_xlpm.n,2,2)),_xlpm.lp,IFERROR(LOOKUP(2,1/(_xlpm.p<>""),_xlpm.p),""),IF(_xlpm.lp="","",INDEX(_xlpm.q,_xlfn.XMATCH(_xlpm.lp,_xlpm.p,0,-1))))} -> 15 | F3: {=_xlfn.LET(_xlpm.key,$B3&"|"&$C3,_xlpm.kdb,价格数据库!$A:$A&"|"&价格数据库!$B:$B,_xlpm.r,_xlfn.XMATCH(_xlpm.key,_xlpm.kdb,0),_xlpm.row,INDEX(价格数据库!$C:$ZZ,_xlpm.r,0),_xlpm.n,INT(COLUMNS(_xlpm.row)/2),_xlpm.p,_xlfn.CHOOSECOLS(_xlpm.row,_xlfn.SEQUENCE(,_xlpm.n,1,2)),_xlpm.pos,_xlfn._xlws.FILTER(_xlfn.SEQUENCE(,COLUMNS(_xlpm.p)),_xlpm.p<>""),IFERROR(INDEX(_xlpm.p,1,INDEX(_xlpm.pos,1,COLUMNS(_xlpm.pos)-1)),""))} -> 5278 | G3: {=_xlfn.LET(_xlpm.key,$B3&"|"&$C3,_xlpm.kdb,价格数据库!$A:$A&"|"&价格数据库!$B:$B,_xlpm.r,_xlfn.XMATCH(_xlpm.key,_xlpm.kdb,0),_xlpm.row,INDEX(价格数据库!$C:$ZZ,_xlpm.r,0),_xlpm.n,INT(COLUMNS(_xlpm.row)/2),_xlpm.q,_xlfn.CHOOSECOLS(_xlpm.row,_xlfn.SEQUENCE(,_xlpm.n,2,2)),_xlpm.pos,_xlfn._xlws.FILTER(_xlfn.SEQUENCE(,COLUMNS(_xlpm.q)),_xlpm.q<>""),IFERROR(INDEX(_xlpm.q,1,INDEX(_xlpm.pos,1,COLUMNS(_xlpm.pos)-1)),""))} -> 16 | H3: {=_xlfn.LET(_xlpm.key,$B3&"|"&$C3,_xlpm.kdb,价格数据库!$A$3:$A$2000&"|"&价格数据库!$B$3:$B$2000,_xlpm.r,_xlfn.XMATCH(_xlpm.key,_xlpm.kdb,0),_xlpm.row,INDEX(价格数据库!$C$3:$ZZ$2000,_xlpm.r,0),_xlpm.n,INT(COLUMNS(_xlpm.row)/2),_xlpm.p,_xlfn.CHOOSECOLS(_xlpm.row,_xlfn.SEQUENCE(,_xlpm.n,1,2)),IFERROR(MIN(_xlfn._xlws.FILTER(_xlpm.p,_xlpm.p<>"")),""))} -> 3997 | I3: {=_xlfn.LET(_xlpm.key,$B3&"|"&$C3,_xlpm.kdb,价格数据库!$A$3:$A$2000&"|"&价格数据库!$B$3:$B$2000,_xlpm.r,_xlfn.XMATCH(_xlpm.key,_xlpm.kdb,0),_xlpm.row,INDEX(价格数据库!$C$3:$ZZ$2000,_xlpm.r,0),_xlpm.n,INT(COLUMNS(_xlpm.row)/2),_xlpm.p,_xlfn.CHOOSECOLS(_xlpm.row,_xlfn.SEQUENCE(,_xlpm.n,1,2)),_xlpm.q,_xlfn.CHOOSECOLS(_xlpm.row,_xlfn.SEQUENCE(,_xlpm.n,2,2)),_xlpm.mp,IFERROR(MIN(_xlfn._xlws.FILTER(_xlpm.p,_xlpm.p<>"")),""),IF(_xlpm.mp="","",INDEX(_xlpm.q,_xlfn.XMATCH(_xlpm.mp,_xlpm.p,0,-1))))} -> 20 | J3: {=_xlfn.LET(_xlpm.key,$B3&"|"&$C3,_xlpm.kdb,价格数据库!$A$3:$A$2000&"|"&价格数据库!$B$3:$B$2000,_xlpm.r,_xlfn.XMATCH(_xlpm.key,_xlpm.kdb,0),_xlpm.row,INDEX(价格数据库!$C$3:$ZZ$2000,_xlpm.r,0),_xlpm.n,INT(COLUMNS(_xlpm.row)/2),_xlpm.p,_xlfn.CHOOSECOLS(_xlpm.row,_xlfn.SEQUENCE(,_xlpm.n,1,2)),IFERROR(MAX(_xlfn._xlws.FILTER(_xlpm.p,_xlpm.p<>"")),""))} -> 5998 | K3: {=_xlfn.LET(_xlpm.key,$B3&"|"&$C3,_xlpm.kdb,价格数据库!$A$3:$A$2000&"|"&价格数据库!$B$3:$B$2000,_xlpm.r,_xlfn.XMATCH(_xlpm.key,_xlpm.kdb,0),_xlpm.row,INDEX(价格数据库!$C$3:$ZZ$2000,_xlpm.r,0),_xlpm.n,INT(COLUMNS(_xlpm.row)/2),_xlpm.p,_xlfn.CHOOSECOLS(_xlpm.row,_xlfn.SEQUENCE(,_xlpm.n,1,2)),_xlpm.q,_xlfn.CHOOSECOLS(_xlpm.row,_xlfn.SEQUENCE(,_xlpm.n,2,2)),_xlpm.mx,IFERROR(MAX(_xlfn._xlws.FILTER(_xlpm.p,_xlpm.p<>"")),""),IF(_xlpm.mx="","",INDEX(_xlpm.q,_xlfn.XMATCH(_xlpm.mx,_xlpm.p,0,-1))))} -> 14 | L3: =J3-H3 -> 2001 | M3: =(D3-H3)/H3 -> 0.27595697 | N3: =(E3-I3)/I3 -> -0.25 | O3: =IFERROR(N3/M3,"") -> -0.90593835 | P3: =IF(O3="","",IF(O3>0,"只卖不买",IF(O3>-0.3,"只卖不买",IF(O3>=-1.5,"交易区",IF(O3>=-2.5,"谨慎","危险盘"))))) -> 交易区 | Q3: =(D3-F3)/F3 -> -0.033724896 | R3: =(E3-G3)/G3 -> -0.0625 | S3: =IFERROR(R3/Q3,"") -> 1.8532303 | T3: =IF(S3="","",IF(S3>0,"只卖不买",IF(S3>-0.3,"只卖不买",IF(S3>=-1.5,"交易区",IF(S3>=-2.5,"谨慎","危险盘"))))) -> 只卖不买 | U3: =IF(D3=H3,"历史最低","")
B4: 火女 | C4: 头 | D4: {=_xlfn.LET(_xlpm.key,$B4&"|"&$C4,_xlpm.kdb,价格数据库!$A$3:$A$2000&"|"&价格数据库!$B$3:$B$2000,_xlpm.r,_xlfn.XMATCH(_xlpm.key,_xlpm.kdb,0),_xlpm.row,INDEX(价格数据库!$C$3:$ZZ$2000,_xlpm.r,0),_xlpm.n,INT(COLUMNS(_xlpm.row)/2),_xlpm.p,_xlfn.CHOOSECOLS(_xlpm.row,_xlfn.SEQUENCE(,_xlpm.n,1,2)),IFERROR(LOOKUP(2,1/(_xlpm.p<>""),_xlpm.p),""))} -> 1885 | E4: {=_xlfn.LET(_xlpm.key,$B4&"|"&$C4,_xlpm.kdb,价格数据库!$A$3:$A$2000&"|"&价格数据库!$B$3:$B$2000,_xlpm.r,_xlfn.XMATCH(_xlpm.key,_xlpm.kdb,0),_xlpm.row,INDEX(价格数据库!$C$3:$ZZ$2000,_xlpm.r,0),_xlpm.n,INT(COLUMNS(_xlpm.row)/2),_xlpm.p,_xlfn.CHOOSECOLS(_xlpm.row,_xlfn.SEQUENCE(,_xlpm.n,1,2)),_xlpm.q,_xlfn.CHOOSECOLS(_xlpm.row,_xlfn.SEQUENCE(,_xlpm.n,2,2)),_xlpm.lp,IFERROR(LOOKUP(2,1/(_xlpm.p<>""),_xlpm.p),""),IF(_xlpm.lp="","",INDEX(_xlpm.q,_xlfn.XMATCH(_xlpm.lp,_xlpm.p,0,-1))))} -> 44 | F4: {=_xlfn.LET(_xlpm.key,$B4&"|"&$C4,_xlpm.kdb,价格数据库!$A:$A&"|"&价格数据库!$B:$B,_xlpm.r,_xlfn.XMATCH(_xlpm.key,_xlpm.kdb,0),_xlpm.row,INDEX(价格数据库!$C:$ZZ,_xlpm.r,0),_xlpm.n,INT(COLUMNS(_xlpm.row)/2),_xlpm.p,_xlfn.CHOOSECOLS(_xlpm.row,_xlfn.SEQUENCE(,_xlpm.n,1,2)),_xlpm.pos,_xlfn._xlws.FILTER(_xlfn.SEQUENCE(,COLUMNS(_xlpm.p)),_xlpm.p<>""),IFERROR(INDEX(_xlpm.p,1,INDEX(_xlpm.pos,1,COLUMNS(_xlpm.pos)-1)),""))} -> 1859 | G4: {=_xlfn.LET(_xlpm.key,$B4&"|"&$C4,_xlpm.kdb,价格数据库!$A:$A&"|"&价格数据库!$B:$B,_xlpm.r,_xlfn.XMATCH(_xlpm.key,_xlpm.kdb,0),_xlpm.row,INDEX(价格数据库!$C:$ZZ,_xlpm.r,0),_xlpm.n,INT(COLUMNS(_xlpm.row)/2),_xlpm.q,_xlfn.CHOOSECOLS(_xlpm.row,_xlfn.SEQUENCE(,_xlpm.n,2,2)),_xlpm.pos,_xlfn._xlws.FILTER(_xlfn.SEQUENCE(,COLUMNS(_xlpm.q)),_xlpm.q<>""),IFERROR(INDEX(_xlpm.q,1,INDEX(_xlpm.pos,1,COLUMNS(_xlpm.pos)-1)),""))} -> 39 | H4: {=_xlfn.LET(_xlpm.key,$B4&"|"&$C4,_xlpm.kdb,价格数据库!$A$3:$A$2000&"|"&价格数据库!$B$3:$B$2000,_xlpm.r,_xlfn.XMATCH(_xlpm.key,_xlpm.kdb,0),_xlpm.row,INDEX(价格数据库!$C$3:$ZZ$2000,_xlpm.r,0),_xlpm.n,INT(COLUMNS(_xlpm.row)/2),_xlpm.p,_xlfn.CHOOSECOLS(_xlpm.row,_xlfn.SEQUENCE(,_xlpm.n,1,2)),IFERROR(MIN(_xlfn._xlws.FILTER(_xlpm.p,_xlpm.p<>"")),""))} -> 1489 | I4: {=_xlfn.LET(_xlpm.key,$B4&"|"&$C4,_xlpm.kdb,价格数据库!$A$3:$A$2000&"|"&价格数据库!$B$3:$B$2000,_xlpm.r,_xlfn.XMATCH(_xlpm.key,_xlpm.kdb,0),_xlpm.row,INDEX(价格数据库!$C$3:$ZZ$2000,_xlpm.r,0),_xlpm.n,INT(COLUMNS(_xlpm.row)/2),_xlpm.p,_xlfn.CHOOSECOLS(_xlpm.row,_xlfn.SEQUENCE(,_xlpm.n,1,2)),_xlpm.q,_xlfn.CHOOSECOLS(_xlpm.row,_xlfn.SEQUENCE(,_xlpm.n,2,2)),_xlpm.mp,IFERROR(MIN(_xlfn._xlws.FILTER(_xlpm.p,_xlpm.p<>"")),""),IF(_xlpm.mp="","",INDEX(_xlpm.q,_xlfn.XMATCH(_xlpm.mp,_xlpm.p,0,-1))))} -> 51 | J4: {=_xlfn.LET(_xlpm.key,$B4&"|"&$C4,_xlpm.kdb,价格数据库!$A$3:$A$2000&"|"&价格数据库!$B$3:$B$2000,_xlpm.r,_xlfn.XMATCH(_xlpm.key,_xlpm.kdb,0),_xlpm.row,INDEX(价格数据库!$C$3:$ZZ$2000,_xlpm.r,0),_xlpm.n,INT(COLUMNS(_xlpm.row)/2),_xlpm.p,_xlfn.CHOOSECOLS(_xlpm.row,_xlfn.SEQUENCE(,_xlpm.n,1,2)),IFERROR(MAX(_xlfn._xlws.FILTER(_xlpm.p,_xlpm.p<>"")),""))} -> 1885 | K4: {=_xlfn.LET(_xlpm.key,$B4&"|"&$C4,_xlpm.kdb,价格数据库!$A$3:$A$2000&"|"&价格数据库!$B$3:$B$2000,_xlpm.r,_xlfn.XMATCH(_xlpm.key,_xlpm.kdb,0),_xlpm.row,INDEX(价格数据库!$C$3:$ZZ$2000,_xlpm.r,0),_xlpm.n,INT(COLUMNS(_xlpm.row)/2),_xlpm.p,_xlfn.CHOOSECOLS(_xlpm.row,_xlfn.SEQUENCE(,_xlpm.n,1,2)),_xlpm.q,_xlfn.CHOOSECOLS(_xlpm.row,_xlfn.SEQUENCE(,_xlpm.n,2,2)),_xlpm.mx,IFERROR(MAX(_xlfn._xlws.FILTER(_xlpm.p,_xlpm.p<>"")),""),IF(_xlpm.mx="","",INDEX(_xlpm.q,_xlfn.XMATCH(_xlpm.mx,_xlpm.p,0,-1))))} -> 44 | L4: =J4-H4 -> 396 | M4: =(D4-H4)/H4 -> 0.2659503 | N4: =(E4-I4)/I4 -> -0.1372549 | O4: =IFERROR(N4/M4,"") -> -0.5160923 | P4: =IF(O4="","",IF(O4>0,"只卖不买",IF(O4>-0.3,"只卖不买",IF(O4>=-1.5,"交易区",IF(O4>=-2.5,"谨慎","危险盘"))))) -> 交易区 | Q4: =(D4-F4)/F4 -> 0.013986014 | R4: =(E4-G4)/G4 -> 0.12820513 | S4: =IFERROR(R4/Q4,"") -> 9.1666667 | T4: =IF(S4="","",IF(S4>0,"只卖不买",IF(S4>-0.3,"只卖不买",IF(S4>=-1.5,"交易区",IF(S4>=-2.5,"谨慎","危险盘"))))) -> 只卖不买 | U4: =IF(D4=H4,"历史最低","")
B5: 小Y | C5: 武器 | D5: {=_xlfn.LET(_xlpm.key,$B5&"|"&$C5,_xlpm.kdb,价格数据库!$A$3:$A$2000&"|"&价格数据库!$B$3:$B$2000,_xlpm.r,_xlfn.XMATCH(_xlpm.key,_xlpm.kdb,0),_xlpm.row,INDEX(价格数据库!$C$3:$ZZ$2000,_xlpm.r,0),_xlpm.n,INT(COLUMNS(_xlpm.row)/2),_xlpm.p,_xlfn.CHOOSECOLS(_xlpm.row,_xlfn.SEQUENCE(,_xlpm.n,1,2)),IFERROR(LOOKUP(2,1/(_xlpm.p<>""),_xlpm.p),""))} -> 8450 | E5: {=_xlfn.LET(_xlpm.key,$B5&"|"&$C5,_xlpm.kdb,价格数据库!$A$3:$A$2000&"|"&价格数据库!$B$3:$B$2000,_xlpm.r,_xlfn.XMATCH(_xlpm.key,_xlpm.kdb,0),_xlpm.row,INDEX(价格数据库!$C$3:$ZZ$2000,_xlpm.r,0),_xlpm.n,INT(COLUMNS(_xlpm.row)/2),_xlpm.p,_xlfn.CHOOSECOLS(_xlpm.row,_xlfn.SEQUENCE(,_xlpm.n,1,2)),_xlpm.q,_xlfn.CHOOSECOLS(_xlpm.row,_xlfn.SEQUENCE(,_xlpm.n,2,2)),_xlpm.lp,IFERROR(LOOKUP(2,1/(_xlpm.p<>""),_xlpm.p),""),IF(_xlpm.lp="","",INDEX(_xlpm.q,_xlfn.XMATCH(_xlpm.lp,_xlpm.p,0,-1))))} -> 9 | F5: {=_xlfn.LET(_xlpm.key,$B5&"|"&$C5,_xlpm.kdb,价格数据库!$A:$A&"|"&价格数据库!$B:$B,_xlpm.r,_xlfn.XMATCH(_xlpm.key,_xlpm.kdb,0),_xlpm.row,INDEX(价格数据库!$C:$ZZ,_xlpm.r,0),_xlpm.n,INT(COLUMNS(_xlpm.row)/2),_xlpm.p,_xlfn.CHOOSECOLS(_xlpm.row,_xlfn.SEQUENCE(,_xlpm.n,1,2)),_xlpm.pos,_xlfn._xlws.FILTER(_xlfn.SEQUENCE(,COLUMNS(_xlpm.p)),_xlpm.p<>""),IFERROR(INDEX(_xlpm.p,1,INDEX(_xlpm.pos,1,COLUMNS(_xlpm.pos)-1)),""))} -> 7000 | G5: {=_xlfn.LET(_xlpm.key,$B5&"|"&$C5,_xlpm.kdb,价格数据库!$A:$A&"|"&价格数据库!$B:$B,_xlpm.r,_xlfn.XMATCH(_xlpm.key,_xlpm.kdb,0),_xlpm.row,INDEX(价格数据库!$C:$ZZ,_xlpm.r,0),_xlpm.n,INT(COLUMNS(_xlpm.row)/2),_xlpm.q,_xlfn.CHOOSECOLS(_xlpm.row,_xlfn.SEQUENCE(,_xlpm.n,2,2)),_xlpm.pos,_xlfn._xlws.FILTER(_xlfn.SEQUENCE(,COLUMNS(_xlpm.q)),_xlpm.q<>""),IFERROR(INDEX(_xlpm.q,1,INDEX(_xlpm.pos,1,COLUMNS(_xlpm.pos)-1)),""))} -> 12 | H5: {=_xlfn.LET(_xlpm.key,$B5&"|"&$C5,_xlpm.kdb,价格数据库!$A$3:$A$2000&"|"&价格数据库!$B$3:$B$2000,_xlpm.r,_xlfn.XMATCH(_xlpm.key,_xlpm.kdb,0),_xlpm.row,INDEX(价格数据库!$C$3:$ZZ$2000,_xlpm.r,0),_xlpm.n,INT(COLUMNS(_xlpm.row)/2),_xlpm.p,_xlfn.CHOOSECOLS(_xlpm.row,_xlfn.SEQUENCE(,_xlpm.n,1,2)),IFERROR(MIN(_xlfn._xlws.FILTER(_xlpm.p,_xlpm.p<>"")),""))} -> 6700 | I5: {=_xlfn.LET(_xlpm.key,$B5&"|"&$C5,_xlpm.kdb,价格数据库!$A$3:$A$2000&"|"&价格数据库!$B$3:$B$2000,_xlpm.r,_xlfn.XMATCH(_xlpm.key,_xlpm.kdb,0),_xlpm.row,INDEX(价格数据库!$C$3:$ZZ$2000,_xlpm.r,0),_xlpm.n,INT(COLUMNS(_xlpm.row)/2),_xlpm.p,_xlfn.CHOOSECOLS(_xlpm.row,_xlfn.SEQUENCE(,_xlpm.n,1,2)),_xlpm.q,_xlfn.CHOOSECOLS(_xlpm.row,_xlfn.SEQUENCE(,_xlpm.n,2,2)),_xlpm.mp,IFERROR(MIN(_xlfn._xlws.FILTER(_xlpm.p,_xlpm.p<>"")),""),IF(_xlpm.mp="","",INDEX(_xlpm.q,_xlfn.XMATCH(_xlpm.mp,_xlpm.p,0,-1))))} -> 12 | J5: {=_xlfn.LET(_xlpm.key,$B5&"|"&$C5,_xlpm.kdb,价格数据库!$A$3:$A$2000&"|"&价格数据库!$B$3:$B$2000,_xlpm.r,_xlfn.XMATCH(_xlpm.key,_xlpm.kdb,0),_xlpm.row,INDEX(价格数据库!$C$3:$ZZ$2000,_xlpm.r,0),_xlpm.n,INT(COLUMNS(_xlpm.row)/2),_xlpm.p,_xlfn.CHOOSECOLS(_xlpm.row,_xlfn.SEQUENCE(,_xlpm.n,1,2)),IFERROR(MAX(_xlfn._xlws.FILTER(_xlpm.p,_xlpm.p<>"")),""))} -> 8600 | K5: {=_xlfn.LET(_xlpm.key,$B5&"|"&$C5,_xlpm.kdb,价格数据库!$A$3:$A$2000&"|"&价格数据库!$B$3:$B$2000,_xlpm.r,_xlfn.XMATCH(_xlpm.key,_xlpm.kdb,0),_xlpm.row,INDEX(价格数据库!$C$3:$ZZ$2000,_xlpm.r,0),_xlpm.n,INT(COLUMNS(_xlpm.row)/2),_xlpm.p,_xlfn.CHOOSECOLS(_xlpm.row,_xlfn.SEQUENCE(,_xlpm.n,1,2)),_xlpm.q,_xlfn.CHOOSECOLS(_xlpm.row,_xlfn.SEQUENCE(,_xlpm.n,2,2)),_xlpm.mx,IFERROR(MAX(_xlfn._xlws.FILTER(_xlpm.p,_xlpm.p<>"")),""),IF(_xlpm.mx="","",INDEX(_xlpm.q,_xlfn.XMATCH(_xlpm.mx,_xlpm.p,0,-1))))} -> 9 | L5: =J5-H5 -> 1900 | M5: =(D5-H5)/H5 -> 0.26119403 | N5: =(E5-I5)/I5 -> -0.25 | O5: =IFERROR(N5/M5,"") -> -0.95714286 | P5: =IF(O5="","",IF(O5>0,"只卖不买",IF(O5>-0.3,"只卖不买",IF(O5>=-1.5,"交易区",IF(O5>=-2.5,"谨慎","危险盘"))))) -> 交易区 | Q5: =(D5-F5)/F5 -> 0.20714286 | R5: =(E5-G5)/G5 -> -0.25 | S5: =IFERROR(R5/Q5,"") -> -1.2068966 | T5: =IF(S5="","",IF(S5>0,"只卖不买",IF(S5>-0.3,"只卖不买",IF(S5>=-1.5,"交易区",IF(S5>=-2.5,"谨慎","危险盘"))))) -> 交易区 | U5: =IF(D5=H5,"历史最低","")
B6: 先知 | C6: 武器 | D6: {=_xlfn.LET(_xlpm.key,$B6&"|"&$C6,_xlpm.kdb,价格数据库!$A$3:$A$2000&"|"&价格数据库!$B$3:$B$2000,_xlpm.r,_xlfn.XMATCH(_xlpm.key,_xlpm.kdb,0),_xlpm.row,INDEX(价格数据库!$C$3:$ZZ$2000,_xlpm.r,0),_xlpm.n,INT(COLUMNS(_xlpm.row)/2),_xlpm.p,_xlfn.CHOOSECOLS(_xlpm.row,_xlfn.SEQUENCE(,_xlpm.n,1,2)),IFERROR(LOOKUP(2,1/(_xlpm.p<>""),_xlpm.p),""))} -> 2595 | E6: {=_xlfn.LET(_xlpm.key,$B6&"|"&$C6,_xlpm.kdb,价格数据库!$A$3:$A$2000&"|"&价格数据库!$B$3:$B$2000,_xlpm.r,_xlfn.XMATCH(_xlpm.key,_xlpm.kdb,0),_xlpm.row,INDEX(价格数据库!$C$3:$ZZ$2000,_xlpm.r,0),_xlpm.n,INT(COLUMNS(_xlpm.row)/2),_xlpm.p,_xlfn.CHOOSECOLS(_xlpm.row,_xlfn.SEQUENCE(,_xlpm.n,1,2)),_xlpm.q,_xlfn.CHOOSECOLS(_xlpm.row,_xlfn.SEQUENCE(,_xlpm.n,2,2)),_xlpm.lp,IFERROR(LOOKUP(2,1/(_xlpm.p<>""),_xlpm.p),""),IF(_xlpm.lp="","",INDEX(_xlpm.q,_xlfn.XMATCH(_xlpm.lp,_xlpm.p,0,-1))))} -> 31 | F6: {=_xlfn.LET(_xlpm.key,$B6&"|"&$C6,_xlpm.kdb,价格数据库!$A:$A&"|"&价格数据库!$B:$B,_xlpm.r,_xlfn.XMATCH(_xlpm.key,_xlpm.kdb,0),_xlpm.row,INDEX(价格数据库!$C:$ZZ,_xlpm.r,0),_xlpm.n,INT(COLUMNS(_xlpm.row)/2),_xlpm.p,_xlfn.CHOOSECOLS(_xlpm.row,_xlfn.SEQUENCE(,_xlpm.n,1,2)),_xlpm.pos,_xlfn._xlws.FILTER(_xlfn.SEQUENCE(,COLUMNS(_xlpm.p)),_xlpm.p<>""),IFERROR(INDEX(_xlpm.p,1,INDEX(_xlpm.pos,1,COLUMNS(_xlpm.pos)-1)),""))} -> 2397 | G6: {=_xlfn.LET(_xlpm.key,$B6&"|"&$C6,_xlpm.kdb,价格数据库!$A:$A&"|"&价格数据库!$B:$B,_xlpm.r,_xlfn.XMATCH(_xlpm.key,_xlpm.kdb,0),_xlpm.row,INDEX(价格数据库!$C:$ZZ,_xlpm.r,0),_xlpm.n,INT(COLUMNS(_xlpm.row)/2),_xlpm.q,_xlfn.CHOOSECOLS(_xlpm.row,_xlfn.SEQUENCE(,_xlpm.n,2,2)),_xlpm.pos,_xlfn._xlws.FILTER(_xlfn.SEQUENCE(,COLUMNS(_xlpm.q)),_xlpm.q<>""),IFERROR(INDEX(_xlpm.q,1,INDEX(_xlpm.pos,1,COLUMNS(_xlpm.pos)-1)),""))} -> 30 | H6: {=_xlfn.LET(_xlpm.key,$B6&"|"&$C6,_xlpm.kdb,价格数据库!$A$3:$A$2000&"|"&价格数据库!$B$3:$B$2000,_xlpm.r,_xlfn.XMATCH(_xlpm.key,_xlpm.kdb,0),_xlpm.row,INDEX(价格数据库!$C$3:$ZZ$2000,_xlpm.r,0),_xlpm.n,INT(COLUMNS(_xlpm.row)/2),_xlpm.p,_xlfn.CHOOSECOLS(_xlpm.row,_xlfn.SEQUENCE(,_xlpm.n,1,2)),IFERROR(MIN(_xlfn._xlws.FILTER(_xlpm.p,_xlpm.p<>"")),""))} -> 2299 | I6: {=_xlfn.LET(_xlpm.key,$B6&"|"&$C6,_xlpm.kdb,价格数据库!$A$3:$A$2000&"|"&价格数据库!$B$3:$B$2000,_xlpm.r,_xlfn.XMATCH(_xlpm.key,_xlpm.kdb,0),_xlpm.row,INDEX(价格数据库!$C$3:$ZZ$2000,_xlpm.r,0),_xlpm.n,INT(COLUMNS(_xlpm.row)/2),_xlpm.p,_xlfn.CHOOSECOLS(_xlpm.row,_xlfn.SEQUENCE(,_xlpm.n,1,2)),_xlpm.q,_xlfn.CHOOSECOLS(_xlpm.row,_xlfn.SEQUENCE(,_xlpm.n,2,2)),_xlpm.mp,IFERROR(MIN(_xlfn._xlws.FILTER(_xlpm.p,_xlpm.p<>"")),""),IF(_xlpm.mp="","",INDEX(_xlpm.q,_xlfn.XMATCH(_xlpm.mp,_xlpm.p,0,-1))))} -> 34 | J6: {=_xlfn.LET(_xlpm.key,$B6&"|"&$C6,_xlpm.kdb,价格数据库!$A$3:$A$2000&"|"&价格数据库!$B$3:$B$2000,_xlpm.r,_xlfn.XMATCH(_xlpm.key,_xlpm.kdb,0),_xlpm.row,INDEX(价格数据库!$C$3:$ZZ$2000,_xlpm.r,0),_xlpm.n,INT(COLUMNS(_xlpm.row)/2),_xlpm.p,_xlfn.CHOOSECOLS(_xlpm.row,_xlfn.SEQUENCE(,_xlpm.n,1,2)),IFERROR(MAX(_xlfn._xlws.FILTER(_xlpm.p,_xlpm.p<>"")),""))} -> 2799 | K6: {=_xlfn.LET(_xlpm.key,$B6&"|"&$C6,_xlpm.kdb,价格数据库!$A$3:$A$2000&"|"&价格数据库!$B$3:$B$2000,_xlpm.r,_xlfn.XMATCH(_xlpm.key,_xlpm.kdb,0),_xlpm.row,INDEX(价格数据库!$C$3:$ZZ$2000,_xlpm.r,0),_xlpm.n,INT(COLUMNS(_xlpm.row)/2),_xlpm.p,_xlfn.CHOOSECOLS(_xlpm.row,_xlfn.SEQUENCE(,_xlpm.n,1,2)),_xlpm.q,_xlfn.CHOOSECOLS(_xlpm.row,_xlfn.SEQUENCE(,_xlpm.n,2,2)),_xlpm.mx,IFERROR(MAX(_xlfn._xlws.FILTER(_xlpm.p,_xlpm.p<>"")),""),IF(_xlpm.mx="","",INDEX(_xlpm.q,_xlfn.XMATCH(_xlpm.mx,_xlpm.p,0,-1))))} -> 23 | L6: =J6-H6 -> 500 | M6: =(D6-H6)/H6 -> 0.12875163 | N6: =(E6-I6)/I6 -> -0.088235294 | O6: =IFERROR(N6/M6,"") -> -0.68531399 | P6: =IF(O6="","",IF(O6>0,"只卖不买",IF(O6>-0.3,"只卖不买",IF(O6>=-1.5,"交易区",IF(O6>=-2.5,"谨慎","危险盘"))))) -> 交易区 | Q6: =(D6-F6)/F6 -> 0.082603254 | R6: =(E6-G6)/G6 -> 0.033333333 | S6: =IFERROR(R6/Q6,"") -> 0.40353535 | T6: =IF(S6="","",IF(S6>0,"只卖不买",IF(S6>-0.3,"只卖不买",IF(S6>=-1.5,"交易区",IF(S6>=-2.5,"谨慎","危险盘"))))) -> 只卖不买 | U6: =IF(D6=H6,"历史最低","")
B7: CK | C7: 坐骑 | D7: {=_xlfn.LET(_xlpm.key,$B7&"|"&$C7,_xlpm.kdb,价格数据库!$A$3:$A$2000&"|"&价格数据库!$B$3:$B$2000,_xlpm.r,_xlfn.XMATCH(_xlpm.key,_xlpm.kdb,0),_xlpm.row,INDEX(价格数据库!$C$3:$ZZ$2000,_xlpm.r,0),_xlpm.n,INT(COLUMNS(_xlpm.row)/2),_xlpm.p,_xlfn.CHOOSECOLS(_xlpm.row,_xlfn.SEQUENCE(,_xlpm.n,1,2)),IFERROR(LOOKUP(2,1/(_xlpm.p<>""),_xlpm.p),""))} -> 1550 | E7: {=_xlfn.LET(_xlpm.key,$B7&"|"&$C7,_xlpm.kdb,价格数据库!$A$3:$A$2000&"|"&价格数据库!$B$3:$B$2000,_xlpm.r,_xlfn.XMATCH(_xlpm.key,_xlpm.kdb,0),_xlpm.row,INDEX(价格数据库!$C$3:$ZZ$2000,_xlpm.r,0),_xlpm.n,INT(COLUMNS(_xlpm.row)/2),_xlpm.p,_xlfn.CHOOSECOLS(_xlpm.row,_xlfn.SEQUENCE(,_xlpm.n,1,2)),_xlpm.q,_xlfn.CHOOSECOLS(_xlpm.row,_xlfn.SEQUENCE(,_xlpm.n,2,2)),_xlpm.lp,IFERROR(LOOKUP(2,1/(_xlpm.p<>""),_xlpm.p),""),IF(_xlpm.lp="","",INDEX(_xlpm.q,_xlfn.XMATCH(_xlpm.lp,_xlpm.p,0,-1))))} -> 44 | F7: {=_xlfn.LET(_xlpm.key,$B7&"|"&$C7,_xlpm.kdb,价格数据库!$A:$A&"|"&价格数据库!$B:$B,_xlpm.r,_xlfn.XMATCH(_xlpm.key,_xlpm.kdb,0),_xlpm.row,INDEX(价格数据库!$C:$ZZ,_xlpm.r,0),_xlpm.n,INT(COLUMNS(_xlpm.row)/2),_xlpm.p,_xlfn.CHOOSECOLS(_xlpm.row,_xlfn.SEQUENCE(,_xlpm.n,1,2)),_xlpm.pos,_xlfn._xlws.FILTER(_xlfn.SEQUENCE(,COLUMNS(_xlpm.p)),_xlpm.p<>""),IFERROR(INDEX(_xlpm.p,1,INDEX(_xlpm.pos,1,COLUMNS(_xlpm.pos)-1)),""))} -> 1779 | G7: {=_xlfn.LET(_xlpm.key,$B7&"|"&$C7,_xlpm.kdb,价格数据库!$A:$A&"|"&价格数据库!$B:$B,_xlpm.r,_xlfn.XMATCH(_xlpm.key,_xlpm.kdb,0),_xlpm.row,INDEX(价格数据库!$C:$ZZ,_xlpm.r,0),_xlpm.n,INT(COLUMNS(_xlpm.row)/2),_xlpm.q,_xlfn.CHOOSECOLS(_xlpm.row,_xlfn.SEQUENCE(,_xlpm.n,2,2)),_xlpm.pos,_xlfn._xlws.FILTER(_xlfn.SEQUENCE(,COLUMNS(_xlpm.q)),_xlpm.q<>""),IFERROR(INDEX(_xlpm.q,1,INDEX(_xlpm.pos,1,COLUMNS(_xlpm.pos)-1)),""))} -> 40 | H7: {=_xlfn.LET(_xlpm.key,$B7&"|"&$C7,_xlpm.kdb,价格数据库!$A$3:$A$2000&"|"&价格数据库!$B$3:$B$2000,_xlpm.r,_xlfn.XMATCH(_xlpm.key,_xlpm.kdb,0),_xlpm.row,INDEX(价格数据库!$C$3:$ZZ$2000,_xlpm.r,0),_xlpm.n,INT(COLUMNS(_xlpm.row)/2),_xlpm.p,_xlfn.CHOOSECOLS(_xlpm.row,_xlfn.SEQUENCE(,_xlpm.n,1,2)),IFERROR(MIN(_xlfn._xlws.FILTER(_xlpm.p,_xlpm.p<>"")),""))} -> 1400 | I7: {=_xlfn.LET(_xlpm.key,$B7&"|"&$C7,_xlpm.kdb,价格数据库!$A$3:$A$2000&"|"&价格数据库!$B$3:$B$2000,_xlpm.r,_xlfn.XMATCH(_xlpm.key,_xlpm.kdb,0),_xlpm.row,INDEX(价格数据库!$C$3:$ZZ$2000,_xlpm.r,0),_xlpm.n,INT(COLUMNS(_xlpm.row)/2),_xlpm.p,_xlfn.CHOOSECOLS(_xlpm.row,_xlfn.SEQUENCE(,_xlpm.n,1,2)),_xlpm.q,_xlfn.CHOOSECOLS(_xlpm.row,_xlfn.SEQUENCE(,_xlpm.n,2,2)),_xlpm.mp,IFERROR(MIN(_xlfn._xlws.FILTER(_xlpm.p,_xlpm.p<>"")),""),IF(_xlpm.mp="","",INDEX(_xlpm.q,_xlfn.XMATCH(_xlpm.mp,_xlpm.p,0,-1))))} -> 52 | J7: {=_xlfn.LET(_xlpm.key,$B7&"|"&$C7,_xlpm.kdb,价格数据库!$A$3:$A$2000&"|"&价格数据库!$B$3:$B$2000,_xlpm.r,_xlfn.XMATCH(_xlpm.key,_xlpm.kdb,0),_xlpm.row,INDEX(价格数据库!$C$3:$ZZ$2000,_xlpm.r,0),_xlpm.n,INT(COLUMNS(_xlpm.row)/2),_xlpm.p,_xlfn.CHOOSECOLS(_xlpm.row,_xlfn.SEQUENCE(,_xlpm.n,1,2)),IFERROR(MAX(_xlfn._xlws.FILTER(_xlpm.p,_xlpm.p<>"")),""))} -> 1779 | K7: {=_xlfn.LET(_xlpm.key,$B7&"|"&$C7,_xlpm.kdb,价格数据库!$A$3:$A$2000&"|"&价格数据库!$B$3:$B$2000,_xlpm.r,_xlfn.XMATCH(_xlpm.key,_xlpm.kdb,0),_xlpm.row,INDEX(价格数据库!$C$3:$ZZ$2000,_xlpm.r,0),_xlpm.n,INT(COLUMNS(_xlpm.row)/2),_xlpm.p,_xlfn.CHOOSECOLS(_xlpm.row,_xlfn.SEQUENCE(,_xlpm.n,1,2)),_xlpm.q,_xlfn.CHOOSECOLS(_xlpm.row,_xlfn.SEQUENCE(,_xlpm.n,2,2)),_xlpm.mx,IFERROR(MAX(_xlfn._xlws.FILTER(_xlpm.p,_xlpm.p<>"")),""),IF(_xlpm.mx="","",INDEX(_xlpm.q,_xlfn.XMATCH(_xlpm.mx,_xlpm.p,0,-1))))} -> 40 | L7: =J7-H7 -> 379 | M7: =(D7-H7)/H7 -> 0.10714286 | N7: =(E7-I7)/I7 -> -0.15384615 | O7: =IFERROR(N7/M7,"") -> -1.4358974 | P7: =IF(O7="","",IF(O7>0,"只卖不买",IF(O7>-0.3,"只卖不买",IF(O7>=-1.5,"交易区",IF(O7>=-2.5,"谨慎","危险盘"))))) -> 交易区 | Q7: =(D7-F7)/F7 -> -0.128724 | R7: =(E7-G7)/G7 -> 0.1 | S7: =IFERROR(R7/Q7,"") -> -0.7768559 | T7: =IF(S7="","",IF(S7>0,"只卖不买",IF(S7>-0.3,"只卖不买",IF(S7>=-1.5,"交易区",IF(S7>=-2.5,"谨慎","危险盘"))))) -> 交易区 | U7: =IF(D7=H7,"历史最低","")
B8: 尸王 | C8: 召唤 | D8: {=_xlfn.LET(_xlpm.key,$B8&"|"&$C8,_xlpm.kdb,价格数据库!$A$3:$A$2000&"|"&价格数据库!$B$3:$B$2000,_xlpm.r,_xlfn.XMATCH(_xlpm.key,_xlpm.kdb,0),_xlpm.row,INDEX(价格数据库!$C$3:$ZZ$2000,_xlpm.r,0),_xlpm.n,INT(COLUMNS(_xlpm.row)/2),_xlpm.p,_xlfn.CHOOSECOLS(_xlpm.row,_xlfn.SEQUENCE(,_xlpm.n,1,2)),IFERROR(LOOKUP(2,1/(_xlpm.p<>""),_xlpm.p),""))} -> 4887 | E8: {=_xlfn.LET(_xlpm.key,$B8&"|"&$C8,_xlpm.kdb,价格数据库!$A$3:$A$2000&"|"&价格数据库!$B$3:$B$2000,_xlpm.r,_xlfn.XMATCH(_xlpm.key,_xlpm.kdb,0),_xlpm.row,INDEX(价格数据库!$C$3:$ZZ$2000,_xlpm.r,0),_xlpm.n,INT(COLUMNS(_xlpm.row)/2),_xlpm.p,_xlfn.CHOOSECOLS(_xlpm.row,_xlfn.SEQUENCE(,_xlpm.n,1,2)),_xlpm.q,_xlfn.CHOOSECOLS(_xlpm.row,_xlfn.SEQUENCE(,_xlpm.n,2,2)),_xlpm.lp,IFERROR(LOOKUP(2,1/(_xlpm.p<>""),_xlpm.p),""),IF(_xlpm.lp="","",INDEX(_xlpm.q,_xlfn.XMATCH(_xlpm.lp,_xlpm.p,0,-1))))} -> 11 | F8: {=_xlfn.LET(_xlpm.key,$B8&"|"&$C8,_xlpm.kdb,价格数据库!$A:$A&"|"&价格数据库!$B:$B,_xlpm.r,_xlfn.XMATCH(_xlpm.key,_xlpm.kdb,0),_xlpm.row,INDEX(价格数据库!$C:$ZZ,_xlpm.r,0),_xlpm.n,INT(COLUMNS(_xlpm.row)/2),_xlpm.p,_xlfn.CHOOSECOLS(_xlpm.row,_xlfn.SEQUENCE(,_xlpm.n,1,2)),_xlpm.pos,_xlfn._xlws.FILTER(_xlfn.SEQUENCE(,COLUMNS(_xlpm.p)),_xlpm.p<>""),IFERROR(INDEX(_xlpm.p,1,INDEX(_xlpm.pos,1,COLUMNS(_xlpm.pos)-1)),""))} -> 4555 | G8: {=_xlfn.LET(_xlpm.key,$B8&"|"&$C8,_xlpm.kdb,价格数据库!$A:$A&"|"&价格数据库!$B:$B,_xlpm.r,_xlfn.XMATCH(_xlpm.key,_xlpm.kdb,0),_xlpm.row,INDEX(价格数据库!$C:$ZZ,_xlpm.r,0),_xlpm.n,INT(COLUMNS(_xlpm.row)/2),_xlpm.q,_xlfn.CHOOSECOLS(_xlpm.row,_xlfn.SEQUENCE(,_xlpm.n,2,2)),_xlpm.pos,_xlfn._xlws.FILTER(_xlfn.SEQUENCE(,COLUMNS(_xlpm.q)),_xlpm.q<>""),IFERROR(INDEX(_xlpm.q,1,INDEX(_xlpm.pos,1,COLUMNS(_xlpm.pos)-1)),""))} -> 13 | H8: {=_xlfn.LET(_xlpm.key,$B8&"|"&$C8,_xlpm.kdb,价格数据库!$A$3:$A$2000&"|"&价格数据库!$B$3:$B$2000,_xlpm.r,_xlfn.XMATCH(_xlpm.key,_xlpm.kdb,0),_xlpm.row,INDEX(价格数据库!$C$3:$ZZ$2000,_xlpm.r,0),_xlpm.n,INT(COLUMNS(_xlpm.row)/2),_xlpm.p,_xlfn.CHOOSECOLS(_xlpm.row,_xlfn.SEQUENCE(,_xlpm.n,1,2)),IFERROR(MIN(_xlfn._xlws.FILTER(_xlpm.p,_xlpm.p<>"")),""))} -> 4555 | I8: {=_xlfn.LET(_xlpm.key,$B8&"|"&$C8,_xlpm.kdb,价格数据库!$A$3:$A$2000&"|"&价格数据库!$B$3:$B$2000,_xlpm.r,_xlfn.XMATCH(_xlpm.key,_xlpm.kdb,0),_xlpm.row,INDEX(价格数据库!$C$3:$ZZ$2000,_xlpm.r,0),_xlpm.n,INT(COLUMNS(_xlpm.row)/2),_xlpm.p,_xlfn.CHOOSECOLS(_xlpm.row,_xlfn.SEQUENCE(,_xlpm.n,1,2)),_xlpm.q,_xlfn.CHOOSECOLS(_xlpm.row,_xlfn.SEQUENCE(,_xlpm.n,2,2)),_xlpm.mp,IFERROR(MIN(_xlfn._xlws.FILTER(_xlpm.p,_xlpm.p<>"")),""),IF(_xlpm.mp="","",INDEX(_xlpm.q,_xlfn.XMATCH(_xlpm.mp,_xlpm.p,0,-1))))} -> 13 | J8: {=_xlfn.LET(_xlpm.key,$B8&"|"&$C8,_xlpm.kdb,价格数据库!$A$3:$A$2000&"|"&价格数据库!$B$3:$B$2000,_xlpm.r,_xlfn.XMATCH(_xlpm.key,_xlpm.kdb,0),_xlpm.row,INDEX(价格数据库!$C$3:$ZZ$2000,_xlpm.r,0),_xlpm.n,INT(COLUMNS(_xlpm.row)/2),_xlpm.p,_xlfn.CHOOSECOLS(_xlpm.row,_xlfn.SEQUENCE(,_xlpm.n,1,2)),IFERROR(MAX(_xlfn._xlws.FILTER(_xlpm.p,_xlpm.p<>"")),""))} -> 5500 | K8: {=_xlfn.LET(_xlpm.key,$B8&"|"&$C8,_xlpm.kdb,价格数据库!$A$3:$A$2000&"|"&价格数据库!$B$3:$B$2000,_xlpm.r,_xlfn.XMATCH(_xlpm.key,_xlpm.kdb,0),_xlpm.row,INDEX(价格数据库!$C$3:$ZZ$2000,_xlpm.r,0),_xlpm.n,INT(COLUMNS(_xlpm.row)/2),_xlpm.p,_xlfn.CHOOSECOLS(_xlpm.row,_xlfn.SEQUENCE(,_xlpm.n,1,2)),_xlpm.q,_xlfn.CHOOSECOLS(_xlpm.row,_xlfn.SEQUENCE(,_xlpm.n,2,2)),_xlpm.mx,IFERROR(MAX(_xlfn._xlws.FILTER(_xlpm.p,_xlpm.p<>"")),""),IF(_xlpm.mx="","",INDEX(_xlpm.q,_xlfn.XMATCH(_xlpm.mx,_xlpm.p,0,-1))))} -> 9 | L8: =J8-H8 -> 945 | M8: =(D8-H8)/H8 -> 0.072886937 | N8: =(E8-I8)/I8 -> -0.15384615 | O8: =IFERROR(N8/M8,"") -> -2.1107507 | P8: =IF(O8="","",IF(O8>0,"只卖不买",IF(O8>-0.3,"只卖不买",IF(O8>=-1.5,"交易区",IF(O8>=-2.5,"谨慎","危险盘"))))) -> 谨慎 | Q8: =(D8-F8)/F8 -> 0.072886937 | R8: =(E8-G8)/G8 -> -0.15384615 | S8: =IFERROR(R8/Q8,"") -> -2.1107507 | T8: =IF(S8="","",IF(S8>0,"只卖不买",IF(S8>-0.3,"只卖不买",IF(S8>=-1.5,"交易区",IF(S8>=-2.5,"谨慎","危险盘"))))) -> 谨慎 | U8: =IF(D8=H8,"历史最低","")
B9: 斧王 | C9: 武器 | D9: {=_xlfn.LET(_xlpm.key,$B9&"|"&$C9,_xlpm.kdb,价格数据库!$A$3:$A$2000&"|"&价格数据库!$B$3:$B$2000,_xlpm.r,_xlfn.XMATCH(_xlpm.key,_xlpm.kdb,0),_xlpm.row,INDEX(价格数据库!$C$3:$ZZ$2000,_xlpm.r,0),_xlpm.n,INT(COLUMNS(_xlpm.row)/2),_xlpm.p,_xlfn.CHOOSECOLS(_xlpm.row,_xlfn.SEQUENCE(,_xlpm.n,1,2)),IFERROR(LOOKUP(2,1/(_xlpm.p<>""),_xlpm.p),""))} -> 1819 | E9: {=_xlfn.LET(_xlpm.key,$B9&"|"&$C9,_xlpm.kdb,价格数据库!$A$3:$A$2000&"|"&价格数据库!$B$3:$B$2000,_xlpm.r,_xlfn.XMATCH(_xlpm.key,_xlpm.kdb,0),_xlpm.row,INDEX(价格数据库!$C$3:$ZZ$2000,_xlpm.r,0),_xlpm.n,INT(COLUMNS(_xlpm.row)/2),_xlpm.p,_xlfn.CHOOSECOLS(_xlpm.row,_xlfn.SEQUENCE(,_xlpm.n,1,2)),_xlpm.q,_xlfn.CHOOSECOLS(_xlpm.row,_xlfn.SEQUENCE(,_xlpm.n,2,2)),_xlpm.lp,IFERROR(LOOKUP(2,1/(_xlpm.p<>""),_xlpm.p),""),IF(_xlpm.lp="","",INDEX(_xlpm.q,_xlfn.XMATCH(_xlpm.lp,_xlpm.p,0,-1))))} -> 44 | F9: {=_xlfn.LET(_xlpm.key,$B9&"|"&$C9,_xlpm.kdb,价格数据库!$A:$A&"|"&价格数据库!$B:$B,_xlpm.r,_xlfn.XMATCH(_xlpm.key,_xlpm.kdb,0),_xlpm.row,INDEX(价格数据库!$C:$ZZ,_xlpm.r,0),_xlpm.n,INT(COLUMNS(_xlpm.row)/2),_xlpm.p,_xlfn.CHOOSECOLS(_xlpm.row,_xlfn.SEQUENCE(,_xlpm.n,1,2)),_xlpm.pos,_xlfn._xlws.FILTER(_xlfn.SEQUENCE(,COLUMNS(_xlpm.p)),_xlpm.p<>""),IFERROR(INDEX(_xlpm.p,1,INDEX(_xlpm.pos,1,COLUMNS(_xlpm.pos)-1)),""))} -> 1749 | G9: {=_xlfn.LET(_xlpm.key,$B9&"|"&$C9,_xlpm.kdb,价格数据库!$A:$A&"|"&价格数据库!$B:$B,_xlpm.r,_xlfn.XMATCH(_xlpm.key,_xlpm.kdb,0),_xlpm.row,INDEX(价格数据库!$C:$ZZ,_xlpm.r,0),_xlpm.n,INT(COLUMNS(_xlpm.row)/2),_xlpm.q,_xlfn.CHOOSECOLS(_xlpm.row,_xlfn.SEQUENCE(,_xlpm.n,2,2)),_xlpm.pos,_xlfn._xlws.FILTER(_xlfn.SEQUENCE(,COLUMNS(_xlpm.q)),_xlpm.q<>""),IFERROR(INDEX(_xlpm.q,1,INDEX(_xlpm.pos,1,COLUMNS(_xlpm.pos)-1)),""))} -> 46 | H9: {=_xlfn.LET(_xlpm.key,$B9&"|"&$C9,_xlpm.kdb,价格数据库!$A$3:$A$2000&"|"&价格数据库!$B$3:$B$2000,_xlpm.r,_xlfn.XMATCH(_xlpm.key,_xlpm.kdb,0),_xlpm.row,INDEX(价格数据库!$C$3:$ZZ$2000,_xlpm.r,0),_xlpm.n,INT(COLUMNS(_xlpm.row)/2),_xlpm.p,_xlfn.CHOOSECOLS(_xlpm.row,_xlfn.SEQUENCE(,_xlpm.n,1,2)),IFERROR(MIN(_xlfn._xlws.FILTER(_xlpm.p,_xlpm.p<>"")),""))} -> 1700 | I9: {=_xlfn.LET(_xlpm.key,$B9&"|"&$C9,_xlpm.kdb,价格数据库!$A$3:$A$2000&"|"&价格数据库!$B$3:$B$2000,_xlpm.r,_xlfn.XMATCH(_xlpm.key,_xlpm.kdb,0),_xlpm.row,INDEX(价格数据库!$C$3:$ZZ$2000,_xlpm.r,0),_xlpm.n,INT(COLUMNS(_xlpm.row)/2),_xlpm.p,_xlfn.CHOOSECOLS(_xlpm.row,_xlfn.SEQUENCE(,_xlpm.n,1,2)),_xlpm.q,_xlfn.CHOOSECOLS(_xlpm.row,_xlfn.SEQUENCE(,_xlpm.n,2,2)),_xlpm.mp,IFERROR(MIN(_xlfn._xlws.FILTER(_xlpm.p,_xlpm.p<>"")),""),IF(_xlpm.mp="","",INDEX(_xlpm.q,_xlfn.XMATCH(_xlpm.mp,_xlpm.p,0,-1))))} -> 39 | J9: {=_xlfn.LET(_xlpm.key,$B9&"|"&$C9,_xlpm.kdb,价格数据库!$A$3:$A$2000&"|"&价格数据库!$B$3:$B$2000,_xlpm.r,_xlfn.XMATCH(_xlpm.key,_xlpm.kdb,0),_xlpm.row,INDEX(价格数据库!$C$3:$ZZ$2000,_xlpm.r,0),_xlpm.n,INT(COLUMNS(_xlpm.row)/2),_xlpm.p,_xlfn.CHOOSECOLS(_xlpm.row,_xlfn.SEQUENCE(,_xlpm.n,1,2)),IFERROR(MAX(_xlfn._xlws.FILTER(_xlpm.p,_xlpm.p<>"")),""))} -> 1947 | K9: {=_xlfn.LET(_xlpm.key,$B9&"|"&$C9,_xlpm.kdb,价格数据库!$A$3:$A$2000&"|"&价格数据库!$B$3:$B$2000,_xlpm.r,_xlfn.XMATCH(_xlpm.key,_xlpm.kdb,0),_xlpm.row,INDEX(价格数据库!$C$3:$ZZ$2000,_xlpm.r,0),_xlpm.n,INT(COLUMNS(_xlpm.row)/2),_xlpm.p,_xlfn.CHOOSECOLS(_xlpm.row,_xlfn.SEQUENCE(,_xlpm.n,1,2)),_xlpm.q,_xlfn.CHOOSECOLS(_xlpm.row,_xlfn.SEQUENCE(,_xlpm.n,2,2)),_xlpm.mx,IFERROR(MAX(_xlfn._xlws.FILTER(_xlpm.p,_xlpm.p<>"")),""),IF(_xlpm.mx="","",INDEX(_xlpm.q,_xlfn.XMATCH(_xlpm.mx,_xlpm.p,0,-1))))} -> 41 | L9: =J9-H9 -> 247 | M9: =(D9-H9)/H9 -> 0.07 | N9: =(E9-I9)/I9 -> 0.12820513 | O9: =IFERROR(N9/M9,"") -> 1.8315018 | P9: =IF(O9="","",IF(O9>0,"只卖不买",IF(O9>-0.3,"只卖不买",IF(O9>=-1.5,"交易区",IF(O9>=-2.5,"谨慎","危险盘"))))) -> 只卖不买 | Q9: =(D9-F9)/F9 -> 0.04002287 | R9: =(E9-G9)/G9 -> -0.043478261 | S9: =IFERROR(R9/Q9,"") -> -1.0863354 | T9: =IF(S9="","",IF(S9>0,"只卖不买",IF(S9>-0.3,"只卖不买",IF(S9>=-1.5,"交易区",IF(S9>=-2.5,"谨慎","危险盘"))))) -> 交易区 | U9: =IF(D9=H9,"历史最低","")
B10: 龙骑 | C10: 武器 | D10: {=_xlfn.LET(_xlpm.key,$B10&"|"&$C10,_xlpm.kdb,价格数据库!$A$3:$A$2000&"|"&价格数据库!$B$3:$B$2000,_xlpm.r,_xlfn.XMATCH(_xlpm.key,_xlpm.kdb,0),_xlpm.row,INDEX(价格数据库!$C$3:$ZZ$2000,_xlpm.r,0),_xlpm.n,INT(COLUMNS(_xlpm.row)/2),_xlpm.p,_xlfn.CHOOSECOLS(_xlpm.row,_xlfn.SEQUENCE(,_xlpm.n,1,2)),IFERROR(LOOKUP(2,1/(_xlpm.p<>""),_xlpm.p),""))} -> 1890 | E10: {=_xlfn.LET(_xlpm.key,$B10&"|"&$C10,_xlpm.kdb,价格数据库!$A$3:$A$2000&"|"&价格数据库!$B$3:$B$2000,_xlpm.r,_xlfn.XMATCH(_xlpm.key,_xlpm.kdb,0),_xlpm.row,INDEX(价格数据库!$C$3:$ZZ$2000,_xlpm.r,0),_xlpm.n,INT(COLUMNS(_xlpm.row)/2),_xlpm.p,_xlfn.CHOOSECOLS(_xlpm.row,_xlfn.SEQUENCE(,_xlpm.n,1,2)),_xlpm.q,_xlfn.CHOOSECOLS(_xlpm.row,_xlfn.SEQUENCE(,_xlpm.n,2,2)),_xlpm.lp,IFERROR(LOOKUP(2,1/(_xlpm.p<>""),_xlpm.p),""),IF(_xlpm.lp="","",INDEX(_xlpm.q,_xlfn.XMATCH(_xlpm.lp,_xlpm.p,0,-1))))} -> 36 | F10: {=_xlfn.LET(_xlpm.key,$B10&"|"&$C10,_xlpm.kdb,价格数据库!$A:$A&"|"&价格数据库!$B:$B,_xlpm.r,_xlfn.XMATCH(_xlpm.key,_xlpm.kdb,0),_xlpm.row,INDEX(价格数据库!$C:$ZZ,_xlpm.r,0),_xlpm.n,INT(COLUMNS(_xlpm.row)/2),_xlpm.p,_xlfn.CHOOSECOLS(_xlpm.row,_xlfn.SEQUENCE(,_xlpm.n,1,2)),_xlpm.pos,_xlfn._xlws.FILTER(_xlfn.SEQUENCE(,COLUMNS(_xlpm.p)),_xlpm.p<>""),IFERROR(INDEX(_xlpm.p,1,INDEX(_xlpm.pos,1,COLUMNS(_xlpm.pos)-1)),""))} -> 1929 | G10: {=_xlfn.LET(_xlpm.key,$B10&"|"&$C10,_xlpm.kdb,价格数据库!$A:$A&"|"&价格数据库!$B:$B,_xlpm.r,_xlfn.XMATCH(_xlpm.key,_xlpm.kdb,0),_xlpm.row,INDEX(价格数据库!$C:$ZZ,_xlpm.r,0),_xlpm.n,INT(COLUMNS(_xlpm.row)/2),_xlpm.q,_xlfn.CHOOSECOLS(_xlpm.row,_xlfn.SEQUENCE(,_xlpm.n,2,2)),_xlpm.pos,_xlfn._xlws.FILTER(_xlfn.SEQUENCE(,COLUMNS(_xlpm.q)),_xlpm.q<>""),IFERROR(INDEX(_xlpm.q,1,INDEX(_xlpm.pos,1,COLUMNS(_xlpm.pos)-1)),""))} -> 37 | H10: {=_xlfn.LET(_xlpm.key,$B10&"|"&$C10,_xlpm.kdb,价格数据库!$A$3:$A$2000&"|"&价格数据库!$B$3:$B$2000,_xlpm.r,_xlfn.XMATCH(_xlpm.key,_xlpm.kdb,0),_xlpm.row,INDEX(价格数据库!$C$3:$ZZ$2000,_xlpm.r,0),_xlpm.n,INT(COLUMNS(_xlpm.row)/2),_xlpm.p,_xlfn.CHOOSECOLS(_xlpm.row,_xlfn.SEQUENCE(,_xlpm.n,1,2)),IFERROR(MIN(_xlfn._xlws.FILTER(_xlpm.p,_xlpm.p<>"")),""))} -> 1799 | I10: {=_xlfn.LET(_xlpm.key,$B10&"|"&$C10,_xlpm.kdb,价格数据库!$A$3:$A$2000&"|"&价格数据库!$B$3:$B$2000,_xlpm.r,_xlfn.XMATCH(_xlpm.key,_xlpm.kdb,0),_xlpm.row,INDEX(价格数据库!$C$3:$ZZ$2000,_xlpm.r,0),_xlpm.n,INT(COLUMNS(_xlpm.row)/2),_xlpm.p,_xlfn.CHOOSECOLS(_xlpm.row,_xlfn.SEQUENCE(,_xlpm.n,1,2)),_xlpm.q,_xlfn.CHOOSECOLS(_xlpm.row,_xlfn.SEQUENCE(,_xlpm.n,2,2)),_xlpm.mp,IFERROR(MIN(_xlfn._xlws.FILTER(_xlpm.p,_xlpm.p<>"")),""),IF(_xlpm.mp="","",INDEX(_xlpm.q,_xlfn.XMATCH(_xlpm.mp,_xlpm.p,0,-1))))} -> 38 | J10: {=_xlfn.LET(_xlpm.key,$B10&"|"&$C10,_xlpm.kdb,价格数据库!$A$3:$A$2000&"|"&价格数据库!$B$3:$B$2000,_xlpm.r,_xlfn.XMATCH(_xlpm.key,_xlpm.kdb,0),_xlpm.row,INDEX(价格数据库!$C$3:$ZZ$2000,_xlpm.r,0),_xlpm.n,INT(COLUMNS(_xlpm.row)/2),_xlpm.p,_xlfn.CHOOSECOLS(_xlpm.row,_xlfn.SEQUENCE(,_xlpm.n,1,2)),IFERROR(MAX(_xlfn._xlws.FILTER(_xlpm.p,_xlpm.p<>"")),""))} -> 1996 | K10: {=_xlfn.LET(_xlpm.key,$B10&"|"&$C10,_xlpm.kdb,价格数据库!$A$3:$A$2000&"|"&价格数据库!$B$3:$B$2000,_xlpm.r,_xlfn.XMATCH(_xlpm.key,_xlpm.kdb,0),_xlpm.row,INDEX(价格数据库!$C$3:$ZZ$2000,_xlpm.r,0),_xlpm.n,INT(COLUMNS(_xlpm.row)/2),_xlpm.p,_xlfn.CHOOSECOLS(_xlpm.row,_xlfn.SEQUENCE(,_xlpm.n,1,2)),_xlpm.q,_xlfn.CHOOSECOLS(_xlpm.row,_xlfn.SEQUENCE(,_xlpm.n,2,2)),_xlpm.mx,IFERROR(MAX(_xlfn._xlws.FILTER(_xlpm.p,_xlpm.p<>"")),""),IF(_xlpm.mx="","",INDEX(_xlpm.q,_xlfn.XMATCH(_xlpm.mx,_xlpm.p,0,-1))))} -> 33 | L10: =J10-H10 -> 197 | M10: =(D10-H10)/H10 -> 0.050583658 | N10: =(E10-I10)/I10 -> -0.052631579 | O10: =IFERROR(N10/M10,"") -> -1.0404858 | P10: =IF(O10="","",IF(O10>0,"只卖不买",IF(O10>-0.3,"只卖不买",IF(O10>=-1.5,"交易区",IF(O10>=-2.5,"谨慎","危险盘"))))) -> 交易区 | Q10: =(D10-F10)/F10 -> -0.020217729 | R10: =(E10-G10)/G10 -> -0.027027027 | S10: =IFERROR(R10/Q10,"") -> 1.3367983 | T10: =IF(S10="","",IF(S10>0,"只卖不买",IF(S10>-0.3,"只卖不买",IF(S10>=-1.5,"交易区",IF(S10>=-2.5,"谨慎","危险盘"))))) -> 只卖不买 | U10: =IF(D10=H10,"历史最低","")
B11: DK | C11: 武器 | D11: {=_xlfn.LET(_xlpm.key,$B11&"|"&$C11,_xlpm.kdb,价格数据库!$A$3:$A$2000&"|"&价格数据库!$B$3:$B$2000,_xlpm.r,_xlfn.XMATCH(_xlpm.key,_xlpm.kdb,0),_xlpm.row,INDEX(价格数据库!$C$3:$ZZ$2000,_xlpm.r,0),_xlpm.n,INT(COLUMNS(_xlpm.row)/2),_xlpm.p,_xlfn.CHOOSECOLS(_xlpm.row,_xlfn.SEQUENCE(,_xlpm.n,1,2)),IFERROR(LOOKUP(2,1/(_xlpm.p<>""),_xlpm.p),""))} -> 1550 | E11: {=_xlfn.LET(_xlpm.key,$B11&"|"&$C11,_xlpm.kdb,价格数据库!$A$3:$A$2000&"|"&价格数据库!$B$3:$B$2000,_xlpm.r,_xlfn.XMATCH(_xlpm.key,_xlpm.kdb,0),_xlpm.row,INDEX(价格数据库!$C$3:$ZZ$2000,_xlpm.r,0),_xlpm.n,INT(COLUMNS(_xlpm.row)/2),_xlpm.p,_xlfn.CHOOSECOLS(_xlpm.row,_xlfn.SEQUENCE(,_xlpm.n,1,2)),_xlpm.q,_xlfn.CHOOSECOLS(_xlpm.row,_xlfn.SEQUENCE(,_xlpm.n,2,2)),_xlpm.lp,IFERROR(LOOKUP(2,1/(_xlpm.p<>""),_xlpm.p),""),IF(_xlpm.lp="","",INDEX(_xlpm.q,_xlfn.XMATCH(_xlpm.lp,_xlpm.p,0,-1))))} -> 47 | F11: {=_xlfn.LET(_xlpm.key,$B11&"|"&$C11,_xlpm.kdb,价格数据库!$A:$A&"|"&价格数据库!$B:$B,_xlpm.r,_xlfn.XMATCH(_xlpm.key,_xlpm.kdb,0),_xlpm.row,INDEX(价格数据库!$C:$ZZ,_xlpm.r,0),_xlpm.n,INT(COLUMNS(_xlpm.row)/2),_xlpm.p,_xlfn.CHOOSECOLS(_xlpm.row,_xlfn.SEQUENCE(,_xlpm.n,1,2)),_xlpm.pos,_xlfn._xlws.FILTER(_xlfn.SEQUENCE(,COLUMNS(_xlpm.p)),_xlpm.p<>""),IFERROR(INDEX(_xlpm.p,1,INDEX(_xlpm.pos,1,COLUMNS(_xlpm.pos)-1)),""))} -> 1538 | G11: {=_xlfn.LET(_xlpm.key,$B11&"|"&$C11,_xlpm.kdb,价格数据库!$A:$A&"|"&价格数据库!$B:$B,_xlpm.r,_xlfn.XMATCH(_xlpm.key,_xlpm.kdb,0),_xlpm.row,INDEX(价格数据库!$C:$ZZ,_xlpm.r,0),_xlpm.n,INT(COLUMNS(_xlpm.row)/2),_xlpm.q,_xlfn.CHOOSECOLS(_xlpm.row,_xlfn.SEQUENCE(,_xlpm.n,2,2)),_xlpm.pos,_xlfn._xlws.FILTER(_xlfn.SEQUENCE(,COLUMNS(_xlpm.q)),_xlpm.q<>""),IFERROR(INDEX(_xlpm.q,1,INDEX(_xlpm.pos,1,COLUMNS(_xlpm.pos)-1)),""))} -> 51 | H11: {=_xlfn.LET(_xlpm.key,$B11&"|"&$C11,_xlpm.kdb,价格数据库!$A$3:$A$2000&"|"&价格数据库!$B$3:$B$2000,_xlpm.r,_xlfn.XMATCH(_xlpm.key,_xlpm.kdb,0),_xlpm.row,INDEX(价格数据库!$C$3:$ZZ$2000,_xlpm.r,0),_xlpm.n,INT(COLUMNS(_xlpm.row)/2),_xlpm.p,_xlfn.CHOOSECOLS(_xlpm.row,_xlfn.SEQUENCE(,_xlpm.n,1,2)),IFERROR(MIN(_xlfn._xlws.FILTER(_xlpm.p,_xlpm.p<>"")),""))} -> 1488 | I11: {=_xlfn.LET(_xlpm.key,$B11&"|"&$C11,_xlpm.kdb,价格数据库!$A$3:$A$2000&"|"&价格数据库!$B$3:$B$2000,_xlpm.r,_xlfn.XMATCH(_xlpm.key,_xlpm.kdb,0),_xlpm.row,INDEX(价格数据库!$C$3:$ZZ$2000,_xlpm.r,0),_xlpm.n,INT(COLUMNS(_xlpm.row)/2),_xlpm.p,_xlfn.CHOOSECOLS(_xlpm.row,_xlfn.SEQUENCE(,_xlpm.n,1,2)),_xlpm.q,_xlfn.CHOOSECOLS(_xlpm.row,_xlfn.SEQUENCE(,_xlpm.n,2,2)),_xlpm.mp,IFERROR(MIN(_xlfn._xlws.FILTER(_xlpm.p,_xlpm.p<>"")),""),IF(_xlpm.mp="","",INDEX(_xlpm.q,_xlfn.XMATCH(_xlpm.mp,_xlpm.p,0,-1))))} -> 54 | J11: {=_xlfn.LET(_xlpm.key,$B11&"|"&$C11,_xlpm.kdb,价格数据库!$A$3:$A$2000&"|"&价格数据库!$B$3:$B$2000,_xlpm.r,_xlfn.XMATCH(_xlpm.key,_xlpm.kdb,0),_xlpm.row,INDEX(价格数据库!$C$3:$ZZ$2000,_xlpm.r,0),_xlpm.n,INT(COLUMNS(_xlpm.row)/2),_xlpm.p,_xlfn.CHOOSECOLS(_xlpm.row,_xlfn.SEQUENCE(,_xlpm.n,1,2)),IFERROR(MAX(_xlfn._xlws.FILTER(_xlpm.p,_xlpm.p<>"")),""))} -> 1698 | K11: {=_xlfn.LET(_xlpm.key,$B11&"|"&$C11,_xlpm.kdb,价格数据库!$A$3:$A$2000&"|"&价格数据库!$B$3:$B$2000,_xlpm.r,_xlfn.XMATCH(_xlpm.key,_xlpm.kdb,0),_xlpm.row,INDEX(价格数据库!$C$3:$ZZ$2000,_xlpm.r,0),_xlpm.n,INT(COLUMNS(_xlpm.row)/2),_xlpm.p,_xlfn.CHOOSECOLS(_xlpm.row,_xlfn.SEQUENCE(,_xlpm.n,1,2)),_xlpm.q,_xlfn.CHOOSECOLS(_xlpm.row,_xlfn.SEQUENCE(,_xlpm.n,2,2)),_xlpm.mx,IFERROR(MAX(_xlfn._xlws.FILTER(_xlpm.p,_xlpm.p<>"")),""),IF(_xlpm.mx="","",INDEX(_xlpm.q,_xlfn.XMATCH(_xlpm.mx,_xlpm.p,0,-1))))} -> 40 | L11: =J11-H11 -> 210 | M11: =(D11-H11)/H11 -> 0.041666667 | N11: =(E11-I11)/I11 -> -0.12962963 | O11: =IFERROR(N11/M11,"") -> -3.1111111 | P11: =IF(O11="","",IF(O11>0,"只卖不买",IF(O11>-0.3,"只卖不买",IF(O11>=-1.5,"交易区",IF(O11>=-2.5,"谨慎","危险盘"))))) -> 危险盘 | Q11: =(D11-F11)/F11 -> 0.0078023407 | R11: =(E11-G11)/G11 -> -0.078431373 | S11: =IFERROR(R11/Q11,"") -> -10.052288 | T11: =IF(S11="","",IF(S11>0,"只卖不买",IF(S11>-0.3,"只卖不买",IF(S11>=-1.5,"交易区",IF(S11>=-2.5,"谨慎","危险盘"))))) -> 危险盘 | U11: =IF(D11=H11,"历史最低","")
B12: 小黑 | C12: 武器 | D12: {=_xlfn.LET(_xlpm.key,$B12&"|"&$C12,_xlpm.kdb,价格数据库!$A$3:$A$2000&"|"&价格数据库!$B$3:$B$2000,_xlpm.r,_xlfn.XMATCH(_xlpm.key,_xlpm.kdb,0),_xlpm.row,INDEX(价格数据库!$C$3:$ZZ$2000,_xlpm.r,0),_xlpm.n,INT(COLUMNS(_xlpm.row)/2),_xlpm.p,_xlfn.CHOOSECOLS(_xlpm.row,_xlfn.SEQUENCE(,_xlpm.n,1,2)),IFERROR(LOOKUP(2,1/(_xlpm.p<>""),_xlpm.p),""))} -> 1900 | E12: {=_xlfn.LET(_xlpm.key,$B12&"|"&$C12,_xlpm.kdb,价格数据库!$A$3:$A$2000&"|"&价格数据库!$B$3:$B$2000,_xlpm.r,_xlfn.XMATCH(_xlpm.key,_xlpm.kdb,0),_xlpm.row,INDEX(价格数据库!$C$3:$ZZ$2000,_xlpm.r,0),_xlpm.n,INT(COLUMNS(_xlpm.row)/2),_xlpm.p,_xlfn.CHOOSECOLS(_xlpm.row,_xlfn.SEQUENCE(,_xlpm.n,1,2)),_xlpm.q,_xlfn.CHOOSECOLS(_xlpm.row,_xlfn.SEQUENCE(,_xlpm.n,2,2)),_xlpm.lp,IFERROR(LOOKUP(2,1/(_xlpm.p<>""),_xlpm.p),""),IF(_xlpm.lp="","",INDEX(_xlpm.q,_xlfn.XMATCH(_xlpm.lp,_xlpm.p,0,-1))))} -> 39 | F12: {=_xlfn.LET(_xlpm.key,$B12&"|"&$C12,_xlpm.kdb,价格数据库!$A:$A&"|"&价格数据库!$B:$B,_xlpm.r,_xlfn.XMATCH(_xlpm.key,_xlpm.kdb,0),_xlpm.row,INDEX(价格数据库!$C:$ZZ,_xlpm.r,0),_xlpm.n,INT(COLUMNS(_xlpm.row)/2),_xlpm.p,_xlfn.CHOOSECOLS(_xlpm.row,_xlfn.SEQUENCE(,_xlpm.n,1,2)),_xlpm.pos,_xlfn._xlws.FILTER(_xlfn.SEQUENCE(,COLUMNS(_xlpm.p)),_xlpm.p<>""),IFERROR(INDEX(_xlpm.p,1,INDEX(_xlpm.pos,1,COLUMNS(_xlpm.pos)-1)),""))} -> 1954 | G12: {=_xlfn.LET(_xlpm.key,$B12&"|"&$C12,_xlpm.kdb,价格数据库!$A:$A&"|"&价格数据库!$B:$B,_xlpm.r,_xlfn.XMATCH(_xlpm.key,_xlpm.kdb,0),_xlpm.row,INDEX(价格数据库!$C:$ZZ,_xlpm.r,0),_xlpm.n,INT(COLUMNS(_xlpm.row)/2),_xlpm.q,_xlfn.CHOOSECOLS(_xlpm.row,_xlfn.SEQUENCE(,_xlpm.n,2,2)),_xlpm.pos,_xlfn._xlws.FILTER(_xlfn.SEQUENCE(,COLUMNS(_xlpm.q)),_xlpm.q<>""),IFERROR(INDEX(_xlpm.q,1,INDEX(_xlpm.pos,1,COLUMNS(_xlpm.pos)-1)),""))} -> 39 | H12: {=_xlfn.LET(_xlpm.key,$B12&"|"&$C12,_xlpm.kdb,价格数据库!$A$3:$A$2000&"|"&价格数据库!$B$3:$B$2000,_xlpm.r,_xlfn.XMATCH(_xlpm.key,_xlpm.kdb,0),_xlpm.row,INDEX(价格数据库!$C$3:$ZZ$2000,_xlpm.r,0),_xlpm.n,INT(COLUMNS(_xlpm.row)/2),_xlpm.p,_xlfn.CHOOSECOLS(_xlpm.row,_xlfn.SEQUENCE(,_xlpm.n,1,2)),IFERROR(MIN(_xlfn._xlws.FILTER(_xlpm.p,_xlpm.p<>"")),""))} -> 1880 | I12: {=_xlfn.LET(_xlpm.key,$B12&"|"&$C12,_xlpm.kdb,价格数据库!$A$3:$A$2000&"|"&价格数据库!$B$3:$B$2000,_xlpm.r,_xlfn.XMATCH(_xlpm.key,_xlpm.kdb,0),_xlpm.row,INDEX(价格数据库!$C$3:$ZZ$2000,_xlpm.r,0),_xlpm.n,INT(COLUMNS(_xlpm.row)/2),_xlpm.p,_xlfn.CHOOSECOLS(_xlpm.row,_xlfn.SEQUENCE(,_xlpm.n,1,2)),_xlpm.q,_xlfn.CHOOSECOLS(_xlpm.row,_xlfn.SEQUENCE(,_xlpm.n,2,2)),_xlpm.mp,IFERROR(MIN(_xlfn._xlws.FILTER(_xlpm.p,_xlpm.p<>"")),""),IF(_xlpm.mp="","",INDEX(_xlpm.q,_xlfn.XMATCH(_xlpm.mp,_xlpm.p,0,-1))))} -> 38 | J12: {=_xlfn.LET(_xlpm.key,$B12&"|"&$C12,_xlpm.kdb,价格数据库!$A$3:$A$2000&"|"&价格数据库!$B$3:$B$2000,_xlpm.r,_xlfn.XMATCH(_xlpm.key,_xlpm.kdb,0),_xlpm.row,INDEX(价格数据库!$C$3:$ZZ$2000,_xlpm.r,0),_xlpm.n,INT(COLUMNS(_xlpm.row)/2),_xlpm.p,_xlfn.CHOOSECOLS(_xlpm.row,_xlfn.SEQUENCE(,_xlpm.n,1,2)),IFERROR(MAX(_xlfn._xlws.FILTER(_xlpm.p,_xlpm.p<>"")),""))} -> 2139 | K12: {=_xlfn.LET(_xlpm.key,$B12&"|"&$C12,_xlpm.kdb,价格数据库!$A$3:$A$2000&"|"&价格数据库!$B$3:$B$2000,_xlpm.r,_xlfn.XMATCH(_xlpm.key,_xlpm.kdb,0),_xlpm.row,INDEX(价格数据库!$C$3:$ZZ$2000,_xlpm.r,0),_xlpm.n,INT(COLUMNS(_xlpm.row)/2),_xlpm.p,_xlfn.CHOOSECOLS(_xlpm.row,_xlfn.SEQUENCE(,_xlpm.n,1,2)),_xlpm.q,_xlfn.CHOOSECOLS(_xlpm.row,_xlfn.SEQUENCE(,_xlpm.n,2,2)),_xlpm.mx,IFERROR(MAX(_xlfn._xlws.FILTER(_xlpm.p,_xlpm.p<>"")),""),IF(_xlpm.mx="","",INDEX(_xlpm.q,_xlfn.XMATCH(_xlpm.mx,_xlpm.p,0,-1))))} -> 31 | L12: =J12-H12 -> 259 | M12: =(D12-H12)/H12 -> 0.010638298 | N12: =(E12-I12)/I12 -> 0.026315789 | O12: =IFERROR(N12/M12,"") -> 2.4736842 | P12: =IF(O12="","",IF(O12>0,"只卖不买",IF(O12>-0.3,"只卖不买",IF(O12>=-1.5,"交易区",IF(O12>=-2.5,"谨慎","危险盘"))))) -> 只卖不买 | Q12: =(D12-F12)/F12 -> -0.027635619 | R12: =(E12-G12)/G12 -> 0 | S12: =IFERROR(R12/Q12,"") -> 0 | T12: =IF(S12="","",IF(S12>0,"只卖不买",IF(S12>-0.3,"只卖不买",IF(S12>=-1.5,"交易区",IF(S12>=-2.5,"谨慎","危险盘"))))) -> 只卖不买 | U12: =IF(D12=H12,"历史最低","")
B13: 海民 | C13: 副手 | D13: {=_xlfn.LET(_xlpm.key,$B13&"|"&$C13,_xlpm.kdb,价格数据库!$A$3:$A$2000&"|"&价格数据库!$B$3:$B$2000,_xlpm.r,_xlfn.XMATCH(_xlpm.key,_xlpm.kdb,0),_xlpm.row,INDEX(价格数据库!$C$3:$ZZ$2000,_xlpm.r,0),_xlpm.n,INT(COLUMNS(_xlpm.row)/2),_xlpm.p,_xlfn.CHOOSECOLS(_xlpm.row,_xlfn.SEQUENCE(,_xlpm.n,1,2)),IFERROR(LOOKUP(2,1/(_xlpm.p<>""),_xlpm.p),""))} -> 1800 | E13: {=_xlfn.LET(_xlpm.key,$B13&"|"&$C13,_xlpm.kdb,价格数据库!$A$3:$A$2000&"|"&价格数据库!$B$3:$B$2000,_xlpm.r,_xlfn.XMATCH(_xlpm.key,_xlpm.kdb,0),_xlpm.row,INDEX(价格数据库!$C$3:$ZZ$2000,_xlpm.r,0),_xlpm.n,INT(COLUMNS(_xlpm.row)/2),_xlpm.p,_xlfn.CHOOSECOLS(_xlpm.row,_xlfn.SEQUENCE(,_xlpm.n,1,2)),_xlpm.q,_xlfn.CHOOSECOLS(_xlpm.row,_xlfn.SEQUENCE(,_xlpm.n,2,2)),_xlpm.lp,IFERROR(LOOKUP(2,1/(_xlpm.p<>""),_xlpm.p),""),IF(_xlpm.lp="","",INDEX(_xlpm.q,_xlfn.XMATCH(_xlpm.lp,_xlpm.p,0,-1))))} -> 34 | F13: {=_xlfn.LET(_xlpm.key,$B13&"|"&$C13,_xlpm.kdb,价格数据库!$A:$A&"|"&价格数据库!$B:$B,_xlpm.r,_xlfn.XMATCH(_xlpm.key,_xlpm.kdb,0),_xlpm.row,INDEX(价格数据库!$C:$ZZ,_xlpm.r,0),_xlpm.n,INT(COLUMNS(_xlpm.row)/2),_xlpm.p,_xlfn.CHOOSECOLS(_xlpm.row,_xlfn.SEQUENCE(,_xlpm.n,1,2)),_xlpm.pos,_xlfn._xlws.FILTER(_xlfn.SEQUENCE(,COLUMNS(_xlpm.p)),_xlpm.p<>""),IFERROR(INDEX(_xlpm.p,1,INDEX(_xlpm.pos,1,COLUMNS(_xlpm.pos)-1)),""))} -> 1949 | G13: {=_xlfn.LET(_xlpm.key,$B13&"|"&$C13,_xlpm.kdb,价格数据库!$A:$A&"|"&价格数据库!$B:$B,_xlpm.r,_xlfn.XMATCH(_xlpm.key,_xlpm.kdb,0),_xlpm.row,INDEX(价格数据库!$C:$ZZ,_xlpm.r,0),_xlpm.n,INT(COLUMNS(_xlpm.row)/2),_xlpm.q,_xlfn.CHOOSECOLS(_xlpm.row,_xlfn.SEQUENCE(,_xlpm.n,2,2)),_xlpm.pos,_xlfn._xlws.FILTER(_xlfn.SEQUENCE(,COLUMNS(_xlpm.q)),_xlpm.q<>""),IFERROR(INDEX(_xlpm.q,1,INDEX(_xlpm.pos,1,COLUMNS(_xlpm.pos)-1)),""))} -> 32 | H13: {=_xlfn.LET(_xlpm.key,$B13&"|"&$C13,_xlpm.kdb,价格数据库!$A$3:$A$2000&"|"&价格数据库!$B$3:$B$2000,_xlpm.r,_xlfn.XMATCH(_xlpm.key,_xlpm.kdb,0),_xlpm.row,INDEX(价格数据库!$C$3:$ZZ$2000,_xlpm.r,0),_xlpm.n,INT(COLUMNS(_xlpm.row)/2),_xlpm.p,_xlfn.CHOOSECOLS(_xlpm.row,_xlfn.SEQUENCE(,_xlpm.n,1,2)),IFERROR(MIN(_xlfn._xlws.FILTER(_xlpm.p,_xlpm.p<>"")),""))} -> 1800 | I13: {=_xlfn.LET(_xlpm.key,$B13&"|"&$C13,_xlpm.kdb,价格数据库!$A$3:$A$2000&"|"&价格数据库!$B$3:$B$2000,_xlpm.r,_xlfn.XMATCH(_xlpm.key,_xlpm.kdb,0),_xlpm.row,INDEX(价格数据库!$C$3:$ZZ$2000,_xlpm.r,0),_xlpm.n,INT(COLUMNS(_xlpm.row)/2),_xlpm.p,_xlfn.CHOOSECOLS(_xlpm.row,_xlfn.SEQUENCE(,_xlpm.n,1,2)),_xlpm.q,_xlfn.CHOOSECOLS(_xlpm.row,_xlfn.SEQUENCE(,_xlpm.n,2,2)),_xlpm.mp,IFERROR(MIN(_xlfn._xlws.FILTER(_xlpm.p,_xlpm.p<>"")),""),IF(_xlpm.mp="","",INDEX(_xlpm.q,_xlfn.XMATCH(_xlpm.mp,_xlpm.p,0,-1))))} -> 34 | J13: {=_xlfn.LET(_xlpm.key,$B13&"|"&$C13,_xlpm.kdb,价格数据库!$A$3:$A$2000&"|"&价格数据库!$B$3:$B$2000,_xlpm.r,_xlfn.XMATCH(_xlpm.key,_xlpm.kdb,0),_xlpm.row,INDEX(价格数据库!$C$3:$ZZ$2000,_xlpm.r,0),_xlpm.n,INT(COLUMNS(_xlpm.row)/2),_xlpm.p,_xlfn.CHOOSECOLS(_xlpm.row,_xlfn.SEQUENCE(,_xlpm.n,1,2)),IFERROR(MAX(_xlfn._xlws.FILTER(_xlpm.p,_xlpm.p<>"")),""))} -> 2200 | K13: {=_xlfn.LET(_xlpm.key,$B13&"|"&$C13,_xlpm.kdb,价格数据库!$A$3:$A$2000&"|"&价格数据库!$B$3:$B$2000,_xlpm.r,_xlfn.XMATCH(_xlpm.key,_xlpm.kdb,0),_xlpm.row,INDEX(价格数据库!$C$3:$ZZ$2000,_xlpm.r,0),_xlpm.n,INT(COLUMNS(_xlpm.row)/2),_xlpm.p,_xlfn.CHOOSECOLS(_xlpm.row,_xlfn.SEQUENCE(,_xlpm.n,1,2)),_xlpm.q,_xlfn.CHOOSECOLS(_xlpm.row,_xlfn.SEQUENCE(,_xlpm.n,2,2)),_xlpm.mx,IFERROR(MAX(_xlfn._xlws.FILTER(_xlpm.p,_xlpm.p<>"")),""),IF(_xlpm.mx="","",INDEX(_xlpm.q,_xlfn.XMATCH(_xlpm.mx,_xlpm.p,0,-1))))} -> 28 | L13: =J13-H13 -> 400 | M13: =(D13-H13)/H13 -> 0 | N13: =(E13-I13)/I13 -> 0 | O13: =IFERROR(N13/M13,"") | P13: =IF(O13="","",IF(O13>0,"只卖不买",IF(O13>-0.3,"只卖不买",IF(O13>=-1.5,"交易区",IF(O13>=-2.5,"谨慎","危险盘"))))) | Q13: =(D13-F13)/F13 -> -0.076449461 | R13: =(E13-G13)/G13 -> 0.0625 | S13: =IFERROR(R13/Q13,"") -> -0.81753356 | T13: =IF(S13="","",IF(S13>0,"只卖不买",IF(S13>-0.3,"只卖不买",IF(S13>=-1.5,"交易区",IF(S13>=-2.5,"谨慎","危险盘"))))) -> 交易区 | U13: =IF(D13=H13,"历史最低","") -> 历史最低
B14: 酒仙 | C14: 副手 | D14: {=_xlfn.LET(_xlpm.key,$B14&"|"&$C14,_xlpm.kdb,价格数据库!$A$3:$A$2000&"|"&价格数据库!$B$3:$B$2000,_xlpm.r,_xlfn.XMATCH(_xlpm.key,_xlpm.kdb,0),_xlpm.row,INDEX(价格数据库!$C$3:$ZZ$2000,_xlpm.r,0),_xlpm.n,INT(COLUMNS(_xlpm.row)/2),_xlpm.p,_xlfn.CHOOSECOLS(_xlpm.row,_xlfn.SEQUENCE(,_xlpm.n,1,2)),IFERROR(LOOKUP(2,1/(_xlpm.p<>""),_xlpm.p),""))} -> 3766 | E14: {=_xlfn.LET(_xlpm.key,$B14&"|"&$C14,_xlpm.kdb,价格数据库!$A$3:$A$2000&"|"&价格数据库!$B$3:$B$2000,_xlpm.r,_xlfn.XMATCH(_xlpm.key,_xlpm.kdb,0),_xlpm.row,INDEX(价格数据库!$C$3:$ZZ$2000,_xlpm.r,0),_xlpm.n,INT(COLUMNS(_xlpm.row)/2),_xlpm.p,_xlfn.CHOOSECOLS(_xlpm.row,_xlfn.SEQUENCE(,_xlpm.n,1,2)),_xlpm.q,_xlfn.CHOOSECOLS(_xlpm.row,_xlfn.SEQUENCE(,_xlpm.n,2,2)),_xlpm.lp,IFERROR(LOOKUP(2,1/(_xlpm.p<>""),_xlpm.p),""),IF(_xlpm.lp="","",INDEX(_xlpm.q,_xlfn.XMATCH(_xlpm.lp,_xlpm.p,0,-1))))} -> 16 | F14: {=_xlfn.LET(_xlpm.key,$B14&"|"&$C14,_xlpm.kdb,价格数据库!$A:$A&"|"&价格数据库!$B:$B,_xlpm.r,_xlfn.XMATCH(_xlpm.key,_xlpm.kdb,0),_xlpm.row,INDEX(价格数据库!$C:$ZZ,_xlpm.r,0),_xlpm.n,INT(COLUMNS(_xlpm.row)/2),_xlpm.p,_xlfn.CHOOSECOLS(_xlpm.row,_xlfn.SEQUENCE(,_xlpm.n,1,2)),_xlpm.pos,_xlfn._xlws.FILTER(_xlfn.SEQUENCE(,COLUMNS(_xlpm.p)),_xlpm.p<>""),IFERROR(INDEX(_xlpm.p,1,INDEX(_xlpm.pos,1,COLUMNS(_xlpm.pos)-1)),""))} -> 3900 | G14: {=_xlfn.LET(_xlpm.key,$B14&"|"&$C14,_xlpm.kdb,价格数据库!$A:$A&"|"&价格数据库!$B:$B,_xlpm.r,_xlfn.XMATCH(_xlpm.key,_xlpm.kdb,0),_xlpm.row,INDEX(价格数据库!$C:$ZZ,_xlpm.r,0),_xlpm.n,INT(COLUMNS(_xlpm.row)/2),_xlpm.q,_xlfn.CHOOSECOLS(_xlpm.row,_xlfn.SEQUENCE(,_xlpm.n,2,2)),_xlpm.pos,_xlfn._xlws.FILTER(_xlfn.SEQUENCE(,COLUMNS(_xlpm.q)),_xlpm.q<>""),IFERROR(INDEX(_xlpm.q,1,INDEX(_xlpm.pos,1,COLUMNS(_xlpm.pos)-1)),""))} -> 14 | H14: {=_xlfn.LET(_xlpm.key,$B14&"|"&$C14,_xlpm.kdb,价格数据库!$A$3:$A$2000&"|"&价格数据库!$B$3:$B$2000,_xlpm.r,_xlfn.XMATCH(_xlpm.key,_xlpm.kdb,0),_xlpm.row,INDEX(价格数据库!$C$3:$ZZ$2000,_xlpm.r,0),_xlpm.n,INT(COLUMNS(_xlpm.row)/2),_xlpm.p,_xlfn.CHOOSECOLS(_xlpm.row,_xlfn.SEQUENCE(,_xlpm.n,1,2)),IFERROR(MIN(_xlfn._xlws.FILTER(_xlpm.p,_xlpm.p<>"")),""))} -> 3766 | I14: {=_xlfn.LET(_xlpm.key,$B14&"|"&$C14,_xlpm.kdb,价格数据库!$A$3:$A$2000&"|"&价格数据库!$B$3:$B$2000,_xlpm.r,_xlfn.XMATCH(_xlpm.key,_xlpm.kdb,0),_xlpm.row,INDEX(价格数据库!$C$3:$ZZ$2000,_xlpm.r,0),_xlpm.n,INT(COLUMNS(_xlpm.row)/2),_xlpm.p,_xlfn.CHOOSECOLS(_xlpm.row,_xlfn.SEQUENCE(,_xlpm.n,1,2)),_xlpm.q,_xlfn.CHOOSECOLS(_xlpm.row,_xlfn.SEQUENCE(,_xlpm.n,2,2)),_xlpm.mp,IFERROR(MIN(_xlfn._xlws.FILTER(_xlpm.p,_xlpm.p<>"")),""),IF(_xlpm.mp="","",INDEX(_xlpm.q,_xlfn.XMATCH(_xlpm.mp,_xlpm.p,0,-1))))} -> 16 | J14: {=_xlfn.LET(_xlpm.key,$B14&"|"&$C14,_xlpm.kdb,价格数据库!$A$3:$A$2000&"|"&价格数据库!$B$3:$B$2000,_xlpm.r,_xlfn.XMATCH(_xlpm.key,_xlpm.kdb,0),_xlpm.row,INDEX(价格数据库!$C$3:$ZZ$2000,_xlpm.r,0),_xlpm.n,INT(COLUMNS(_xlpm.row)/2),_xlpm.p,_xlfn.CHOOSECOLS(_xlpm.row,_xlfn.SEQUENCE(,_xlpm.n,1,2)),IFERROR(MAX(_xlfn._xlws.FILTER(_xlpm.p,_xlpm.p<>"")),""))} -> 4700 | K14: {=_xlfn.LET(_xlpm.key,$B14&"|"&$C14,_xlpm.kdb,价格数据库!$A$3:$A$2000&"|"&价格数据库!$B$3:$B$2000,_xlpm.r,_xlfn.XMATCH(_xlpm.key,_xlpm.kdb,0),_xlpm.row,INDEX(价格数据库!$C$3:$ZZ$2000,_xlpm.r,0),_xlpm.n,INT(COLUMNS(_xlpm.row)/2),_xlpm.p,_xlfn.CHOOSECOLS(_xlpm.row,_xlfn.SEQUENCE(,_xlpm.n,1,2)),_xlpm.q,_xlfn.CHOOSECOLS(_xlpm.row,_xlfn.SEQUENCE(,_xlpm.n,2,2)),_xlpm.mx,IFERROR(MAX(_xlfn._xlws.FILTER(_xlpm.p,_xlpm.p<>"")),""),IF(_xlpm.mx="","",INDEX(_xlpm.q,_xlfn.XMATCH(_xlpm.mx,_xlpm.p,0,-1))))} -> 14 | L14: =J14-H14 -> 934 | M14: =(D14-H14)/H14 -> 0 | N14: =(E14-I14)/I14 -> 0 | O14: =IFERROR(N14/M14,"") | P14: =IF(O14="","",IF(O14>0,"只卖不买",IF(O14>-0.3,"只卖不买",IF(O14>=-1.5,"交易区",IF(O14>=-2.5,"谨慎","危险盘"))))) | Q14: =(D14-F14)/F14 -> -0.034358974 | R14: =(E14-G14)/G14 -> 0.14285714 | S14: =IFERROR(R14/Q14,"") -> -4.1577825 | T14: =IF(S14="","",IF(S14>0,"只卖不买",IF(S14>-0.3,"只卖不买",IF(S14>=-1.5,"交易区",IF(S14>=-2.5,"谨慎","危险盘"))))) -> 危险盘 | U14: =IF(D14=H14,"历史最低","") -> 历史最低
B15: 冰女 | C15: 武器 | D15: {=_xlfn.LET(_xlpm.key,$B15&"|"&$C15,_xlpm.kdb,价格数据库!$A$3:$A$2000&"|"&价格数据库!$B$3:$B$2000,_xlpm.r,_xlfn.XMATCH(_xlpm.key,_xlpm.kdb,0),_xlpm.row,INDEX(价格数据库!$C$3:$ZZ$2000,_xlpm.r,0),_xlpm.n,INT(COLUMNS(_xlpm.row)/2),_xlpm.p,_xlfn.CHOOSECOLS(_xlpm.row,_xlfn.SEQUENCE(,_xlpm.n,1,2)),IFERROR(LOOKUP(2,1/(_xlpm.p<>""),_xlpm.p),""))} -> 8500 | E15: {=_xlfn.LET(_xlpm.key,$B15&"|"&$C15,_xlpm.kdb,价格数据库!$A$3:$A$2000&"|"&价格数据库!$B$3:$B$2000,_xlpm.r,_xlfn.XMATCH(_xlpm.key,_xlpm.kdb,0),_xlpm.row,INDEX(价格数据库!$C$3:$ZZ$2000,_xlpm.r,0),_xlpm.n,INT(COLUMNS(_xlpm.row)/2),_xlpm.p,_xlfn.CHOOSECOLS(_xlpm.row,_xlfn.SEQUENCE(,_xlpm.n,1,2)),_xlpm.q,_xlfn.CHOOSECOLS(_xlpm.row,_xlfn.SEQUENCE(,_xlpm.n,2,2)),_xlpm.lp,IFERROR(LOOKUP(2,1/(_xlpm.p<>""),_xlpm.p),""),IF(_xlpm.lp="","",INDEX(_xlpm.q,_xlfn.XMATCH(_xlpm.lp,_xlpm.p,0,-1))))} -> 8 | F15: {=_xlfn.LET(_xlpm.key,$B15&"|"&$C15,_xlpm.kdb,价格数据库!$A:$A&"|"&价格数据库!$B:$B,_xlpm.r,_xlfn.XMATCH(_xlpm.key,_xlpm.kdb,0),_xlpm.row,INDEX(价格数据库!$C:$ZZ,_xlpm.r,0),_xlpm.n,INT(COLUMNS(_xlpm.row)/2),_xlpm.p,_xlfn.CHOOSECOLS(_xlpm.row,_xlfn.SEQUENCE(,_xlpm.n,1,2)),_xlpm.pos,_xlfn._xlws.FILTER(_xlfn.SEQUENCE(,COLUMNS(_xlpm.p)),_xlpm.p<>""),IFERROR(INDEX(_xlpm.p,1,INDEX(_xlpm.pos,1,COLUMNS(_xlpm.pos)-1)),""))} -> 8500 | G15: {=_xlfn.LET(_xlpm.key,$B15&"|"&$C15,_xlpm.kdb,价格数据库!$A:$A&"|"&价格数据库!$B:$B,_xlpm.r,_xlfn.XMATCH(_xlpm.key,_xlpm.kdb,0),_xlpm.row,INDEX(价格数据库!$C:$ZZ,_xlpm.r,0),_xlpm.n,INT(COLUMNS(_xlpm.row)/2),_xlpm.q,_xlfn.CHOOSECOLS(_xlpm.row,_xlfn.SEQUENCE(,_xlpm.n,2,2)),_xlpm.pos,_xlfn._xlws.FILTER(_xlfn.SEQUENCE(,COLUMNS(_xlpm.q)),_xlpm.q<>""),IFERROR(INDEX(_xlpm.q,1,INDEX(_xlpm.pos,1,COLUMNS(_xlpm.pos)-1)),""))} -> 8 | H15: {=_xlfn.LET(_xlpm.key,$B15&"|"&$C15,_xlpm.kdb,价格数据库!$A$3:$A$2000&"|"&价格数据库!$B$3:$B$2000,_xlpm.r,_xlfn.XMATCH(_xlpm.key,_xlpm.kdb,0),_xlpm.row,INDEX(价格数据库!$C$3:$ZZ$2000,_xlpm.r,0),_xlpm.n,INT(COLUMNS(_xlpm.row)/2),_xlpm.p,_xlfn.CHOOSECOLS(_xlpm.row,_xlfn.SEQUENCE(,_xlpm.n,1,2)),IFERROR(MIN(_xlfn._xlws.FILTER(_xlpm.p,_xlpm.p<>"")),""))} -> 8500 | I15: {=_xlfn.LET(_xlpm.key,$B15&"|"&$C15,_xlpm.kdb,价格数据库!$A$3:$A$2000&"|"&价格数据库!$B$3:$B$2000,_xlpm.r,_xlfn.XMATCH(_xlpm.key,_xlpm.kdb,0),_xlpm.row,INDEX(价格数据库!$C$3:$ZZ$2000,_xlpm.r,0),_xlpm.n,INT(COLUMNS(_xlpm.row)/2),_xlpm.p,_xlfn.CHOOSECOLS(_xlpm.row,_xlfn.SEQUENCE(,_xlpm.n,1,2)),_xlpm.q,_xlfn.CHOOSECOLS(_xlpm.row,_xlfn.SEQUENCE(,_xlpm.n,2,2)),_xlpm.mp,IFERROR(MIN(_xlfn._xlws.FILTER(_xlpm.p,_xlpm.p<>"")),""),IF(_xlpm.mp="","",INDEX(_xlpm.q,_xlfn.XMATCH(_xlpm.mp,_xlpm.p,0,-1))))} -> 8 | J15: {=_xlfn.LET(_xlpm.key,$B15&"|"&$C15,_xlpm.kdb,价格数据库!$A$3:$A$2000&"|"&价格数据库!$B$3:$B$2000,_xlpm.r,_xlfn.XMATCH(_xlpm.key,_xlpm.kdb,0),_xlpm.row,INDEX(价格数据库!$C$3:$ZZ$2000,_xlpm.r,0),_xlpm.n,INT(COLUMNS(_xlpm.row)/2),_xlpm.p,_xlfn.CHOOSECOLS(_xlpm.row,_xlfn.SEQUENCE(,_xlpm.n,1,2)),IFERROR(MAX(_xlfn._xlws.FILTER(_xlpm.p,_xlpm.p<>"")),""))} -> 10000 | K15: {=_xlfn.LET(_xlpm.key,$B15&"|"&$C15,_xlpm.kdb,价格数据库!$A$3:$A$2000&"|"&价格数据库!$B$3:$B$2000,_xlpm.r,_xlfn.XMATCH(_xlpm.key,_xlpm.kdb,0),_xlpm.row,INDEX(价格数据库!$C$3:$ZZ$2000,_xlpm.r,0),_xlpm.n,INT(COLUMNS(_xlpm.row)/2),_xlpm.p,_xlfn.CHOOSECOLS(_xlpm.row,_xlfn.SEQUENCE(,_xlpm.n,1,2)),_xlpm.q,_xlfn.CHOOSECOLS(_xlpm.row,_xlfn.SEQUENCE(,_xlpm.n,2,2)),_xlpm.mx,IFERROR(MAX(_xlfn._xlws.FILTER(_xlpm.p,_xlpm.p<>"")),""),IF(_xlpm.mx="","",INDEX(_xlpm.q,_xlfn.XMATCH(_xlpm.mx,_xlpm.p,0,-1))))} -> 6 | L15: =J15-H15 -> 1500 | M15: =(D15-H15)/H15 -> 0 | N15: =(E15-I15)/I15 -> 0 | O15: =IFERROR(N15/M15,"") | P15: =IF(O15="","",IF(O15>0,"只卖不买",IF(O15>-0.3,"只卖不买",IF(O15>=-1.5,"交易区",IF(O15>=-2.5,"谨慎","危险盘"))))) | Q15: =(D15-F15)/F15 -> 0 | R15: =(E15-G15)/G15 -> 0 | S15: =IFERROR(R15/Q15,"") | T15: =IF(S15="","",IF(S15>0,"只卖不买",IF(S15>-0.3,"只卖不买",IF(S15>=-1.5,"交易区",IF(S15>=-2.5,"谨慎","危险盘"))))) | U15: =IF(D15=H15,"历史最低","") -> 历史最低
B17: 英雄 | C17: 部位 | D17: 目前价格 | E17: 目前数量 | F17: 上期价格 | G17: 上期数量 | H17: 最低价格 | I17: 最低数量 | J17: 列2 | K17: 价格同比 | L17: 数量同比 | M17: 同比弹性 | N17: 同比评价 | O17: 价格环比 | P17: 数量环比 | Q17: 环比弹性 | R17: 环比评价 | S17: 列3 | T17: 最高价格 | U17: 最高数量
B18: 蓝猫 | C18: 头 | D18: {=_xlfn.LET(_xlpm.key,$B18&"|"&$C18,_xlpm.kdb,价格数据库!$A$3:$A$2000&"|"&价格数据库!$B$3:$B$2000,_xlpm.r,_xlfn.XMATCH(_xlpm.key,_xlpm.kdb,0),_xlpm.row,INDEX(价格数据库!$C$3:$ZZ$2000,_xlpm.r,0),_xlpm.n,INT(COLUMNS(_xlpm.row)/2),_xlpm.p,_xlfn.CHOOSECOLS(_xlpm.row,_xlfn.SEQUENCE(,_xlpm.n,1,2)),IFERROR(LOOKUP(2,1/(_xlpm.p<>""),_xlpm.p),""))} -> 0 | E18: {=_xlfn.LET(_xlpm.key,$B18&"|"&$C18,_xlpm.kdb,价格数据库!$A$3:$A$2000&"|"&价格数据库!$B$3:$B$2000,_xlpm.r,_xlfn.XMATCH(_xlpm.key,_xlpm.kdb,0),_xlpm.row,INDEX(价格数据库!$C$3:$ZZ$2000,_xlpm.r,0),_xlpm.n,INT(COLUMNS(_xlpm.row)/2),_xlpm.p,_xlfn.CHOOSECOLS(_xlpm.row,_xlfn.SEQUENCE(,_xlpm.n,1,2)),_xlpm.q,_xlfn.CHOOSECOLS(_xlpm.row,_xlfn.SEQUENCE(,_xlpm.n,2,2)),_xlpm.lp,IFERROR(LOOKUP(2,1/(_xlpm.p<>""),_xlpm.p),""),IF(_xlpm.lp="","",INDEX(_xlpm.q,_xlfn.XMATCH(_xlpm.lp,_xlpm.p,0,-1))))} -> 0 | F18: {=_xlfn.LET(_xlpm.key,$B18&"|"&$C18,_xlpm.kdb,价格数据库!$A:$A&"|"&价格数据库!$B:$B,_xlpm.r,_xlfn.XMATCH(_xlpm.key,_xlpm.kdb,0),_xlpm.row,INDEX(价格数据库!$C:$ZZ,_xlpm.r,0),_xlpm.n,INT(COLUMNS(_xlpm.row)/2),_xlpm.p,_xlfn.CHOOSECOLS(_xlpm.row,_xlfn.SEQUENCE(,_xlpm.n,1,2)),_xlpm.pos,_xlfn._xlws.FILTER(_xlfn.SEQUENCE(,COLUMNS(_xlpm.p)),_xlpm.p<>""),IFERROR(INDEX(_xlpm.p,1,INDEX(_xlpm.pos,1,COLUMNS(_xlpm.pos)-1)),""))} -> 0 | G18: {=_xlfn.LET(_xlpm.key,$B18&"|"&$C18,_xlpm.kdb,价格数据库!$A:$A&"|"&价格数据库!$B:$B,_xlpm.r,_xlfn.XMATCH(_xlpm.key,_xlpm.kdb,0),_xlpm.row,INDEX(价格数据库!$C:$ZZ,_xlpm.r,0),_xlpm.n,INT(COLUMNS(_xlpm.row)/2),_xlpm.q,_xlfn.CHOOSECOLS(_xlpm.row,_xlfn.SEQUENCE(,_xlpm.n,2,2)),_xlpm.pos,_xlfn._xlws.FILTER(_xlfn.SEQUENCE(,COLUMNS(_xlpm.q)),_xlpm.q<>""),IFERROR(INDEX(_xlpm.q,1,INDEX(_xlpm.pos,1,COLUMNS(_xlpm.pos)-1)),""))} -> 0 | H18: {=_xlfn.LET(_xlpm.key,$B18&"|"&$C18,_xlpm.kdb,价格数据库!$A$3:$A$2000&"|"&价格数据库!$B$3:$B$2000,_xlpm.r,_xlfn.XMATCH(_xlpm.key,_xlpm.kdb,0),_xlpm.row,INDEX(价格数据库!$C$3:$ZZ$2000,_xlpm.r,0),_xlpm.n,INT(COLUMNS(_xlpm.row)/2),_xlpm.p,_xlfn.CHOOSECOLS(_xlpm.row,_xlfn.SEQUENCE(,_xlpm.n,1,2)),IFERROR(MIN(_xlfn._xlws.FILTER(_xlpm.p,_xlpm.p<>"")),""))} -> 0 | I18: {=_xlfn.LET(_xlpm.key,$B18&"|"&$C18,_xlpm.kdb,价格数据库!$A$3:$A$2000&"|"&价格数据库!$B$3:$B$2000,_xlpm.r,_xlfn.XMATCH(_xlpm.key,_xlpm.kdb,0),_xlpm.row,INDEX(价格数据库!$C$3:$ZZ$2000,_xlpm.r,0),_xlpm.n,INT(COLUMNS(_xlpm.row)/2),_xlpm.p,_xlfn.CHOOSECOLS(_xlpm.row,_xlfn.SEQUENCE(,_xlpm.n,1,2)),_xlpm.q,_xlfn.CHOOSECOLS(_xlpm.row,_xlfn.SEQUENCE(,_xlpm.n,2,2)),_xlpm.mp,IFERROR(MIN(_xlfn._xlws.FILTER(_xlpm.p,_xlpm.p<>"")),""),IF(_xlpm.mp="","",INDEX(_xlpm.q,_xlfn.XMATCH(_xlpm.mp,_xlpm.p,0,-1))))} -> 0 | J18: =IF(D18=H18,"历史最低","") -> 历史最低 | K18: =(D18-H18)/H18 -> #DIV/0! | L18: =(E18-I18)/I18 -> #DIV/0! | M18: =IFERROR(L18/K18,"") | N18: =IF(M18="","",IF(M18>0,"只卖不买",IF(M18>-0.3,"只卖不买",IF(M18>=-1.5,"交易区",IF(M18>=-2.5,"谨慎","危险盘"))))) | O18: =(D18-F18)/F18 -> #DIV/0! | P18: =(E18-G18)/G18 -> #DIV/0! | Q18: =IFERROR(P18/O18,"") | R18: =IF(Q18="","",IF(Q18>0,"只卖不买",IF(Q18>-0.3,"只卖不买",IF(Q18>=-1.5,"交易区",IF(Q18>=-2.5,"谨慎","危险盘"))))) | S18: =IF(AND(N18="交易区",R18="交易区"),"双绿","") | T18: {=_xlfn.LET(_xlpm.key,$B18&"|"&$C18,_xlpm.kdb,价格数据库!$A$3:$A$2000&"|"&价格数据库!$B$3:$B$2000,_xlpm.r,_xlfn.XMATCH(_xlpm.key,_xlpm.kdb,0),_xlpm.row,INDEX(价格数据库!$C$3:$ZZ$2000,_xlpm.r,0),_xlpm.n,INT(COLUMNS(_xlpm.row)/2),_xlpm.p,_xlfn.CHOOSECOLS(_xlpm.row,_xlfn.SEQUENCE(,_xlpm.n,1,2)),IFERROR(MAX(_xlfn._xlws.FILTER(_xlpm.p,_xlpm.p<>"")),""))} -> 150000 | U18: {=_xlfn.LET(_xlpm.key,$B18&"|"&$C18,_xlpm.kdb,价格数据库!$A$3:$A$2000&"|"&价格数据库!$B$3:$B$2000,_xlpm.r,_xlfn.XMATCH(_xlpm.key,_xlpm.kdb,0),_xlpm.row,INDEX(价格数据库!$C$3:$ZZ$2000,_xlpm.r,0),_xlpm.n,INT(COLUMNS(_xlpm.row)/2),_xlpm.p,_xlfn.CHOOSECOLS(_xlpm.row,_xlfn.SEQUENCE(,_xlpm.n,1,2)),_xlpm.q,_xlfn.CHOOSECOLS(_xlpm.row,_xlfn.SEQUENCE(,_xlpm.n,2,2)),_xlpm.mx,IFERROR(MAX(_xlfn._xlws.FILTER(_xlpm.p,_xlpm.p<>"")),""),IF(_xlpm.mx="","",INDEX(_xlpm.q,_xlfn.XMATCH(_xlpm.mx,_xlpm.p,0,-1))))} -> 1
B19: 小鱼 | C19: 武器 | D19: {=_xlfn.LET(_xlpm.key,$B19&"|"&$C19,_xlpm.kdb,价格数据库!$A$3:$A$2000&"|"&价格数据库!$B$3:$B$2000,_xlpm.r,_xlfn.XMATCH(_xlpm.key,_xlpm.kdb,0),_xlpm.row,INDEX(价格数据库!$C$3:$ZZ$2000,_xlpm.r,0),_xlpm.n,INT(COLUMNS(_xlpm.row)/2),_xlpm.p,_xlfn.CHOOSECOLS(_xlpm.row,_xlfn.SEQUENCE(,_xlpm.n,1,2)),IFERROR(LOOKUP(2,1/(_xlpm.p<>""),_xlpm.p),""))} -> 27000 | E19: {=_xlfn.LET(_xlpm.key,$B19&"|"&$C19,_xlpm.kdb,价格数据库!$A$3:$A$2000&"|"&价格数据库!$B$3:$B$2000,_xlpm.r,_xlfn.XMATCH(_xlpm.key,_xlpm.kdb,0),_xlpm.row,INDEX(价格数据库!$C$3:$ZZ$2000,_xlpm.r,0),_xlpm.n,INT(COLUMNS(_xlpm.row)/2),_xlpm.p,_xlfn.CHOOSECOLS(_xlpm.row,_xlfn.SEQUENCE(,_xlpm.n,1,2)),_xlpm.q,_xlfn.CHOOSECOLS(_xlpm.row,_xlfn.SEQUENCE(,_xlpm.n,2,2)),_xlpm.lp,IFERROR(LOOKUP(2,1/(_xlpm.p<>""),_xlpm.p),""),IF(_xlpm.lp="","",INDEX(_xlpm.q,_xlfn.XMATCH(_xlpm.lp,_xlpm.p,0,-1))))} -> 2 | F19: {=_xlfn.LET(_xlpm.key,$B19&"|"&$C19,_xlpm.kdb,价格数据库!$A:$A&"|"&价格数据库!$B:$B,_xlpm.r,_xlfn.XMATCH(_xlpm.key,_xlpm.kdb,0),_xlpm.row,INDEX(价格数据库!$C:$ZZ,_xlpm.r,0),_xlpm.n,INT(COLUMNS(_xlpm.row)/2),_xlpm.p,_xlfn.CHOOSECOLS(_xlpm.row,_xlfn.SEQUENCE(,_xlpm.n,1,2)),_xlpm.pos,_xlfn._xlws.FILTER(_xlfn.SEQUENCE(,COLUMNS(_xlpm.p)),_xlpm.p<>""),IFERROR(INDEX(_xlpm.p,1,INDEX(_xlpm.pos,1,COLUMNS(_xlpm.pos)-1)),""))} -> 27000 | G19: {=_xlfn.LET(_xlpm.key,$B19&"|"&$C19,_xlpm.kdb,价格数据库!$A:$A&"|"&价格数据库!$B:$B,_xlpm.r,_xlfn.XMATCH(_xlpm.key,_xlpm.kdb,0),_xlpm.row,INDEX(价格数据库!$C:$ZZ,_xlpm.r,0),_xlpm.n,INT(COLUMNS(_xlpm.row)/2),_xlpm.q,_xlfn.CHOOSECOLS(_xlpm.row,_xlfn.SEQUENCE(,_xlpm.n,2,2)),_xlpm.pos,_xlfn._xlws.FILTER(_xlfn.SEQUENCE(,COLUMNS(_xlpm.q)),_xlpm.q<>""),IFERROR(INDEX(_xlpm.q,1,INDEX(_xlpm.pos,1,COLUMNS(_xlpm.pos)-1)),""))} -> 3 | H19: {=_xlfn.LET(_xlpm.key,$B19&"|"&$C19,_xlpm.kdb,价格数据库!$A$3:$A$2000&"|"&价格数据库!$B$3:$B$2000,_xlpm.r,_xlfn.XMATCH(_xlpm.key,_xlpm.kdb,0),_xlpm.row,INDEX(价格数据库!$C$3:$ZZ$2000,_xlpm.r,0),_xlpm.n,INT(COLUMNS(_xlpm.row)/2),_xlpm.p,_xlfn.CHOOSECOLS(_xlpm.row,_xlfn.SEQUENCE(,_xlpm.n,1,2)),IFERROR(MIN(_xlfn._xlws.FILTER(_xlpm.p,_xlpm.p<>"")),""))} -> 15200 | I19: {=_xlfn.LET(_xlpm.key,$B19&"|"&$C19,_xlpm.kdb,价格数据库!$A$3:$A$2000&"|"&价格数据库!$B$3:$B$2000,_xlpm.r,_xlfn.XMATCH(_xlpm.key,_xlpm.kdb,0),_xlpm.row,INDEX(价格数据库!$C$3:$ZZ$2000,_xlpm.r,0),_xlpm.n,INT(COLUMNS(_xlpm.row)/2),_xlpm.p,_xlfn.CHOOSECOLS(_xlpm.row,_xlfn.SEQUENCE(,_xlpm.n,1,2)),_xlpm.q,_xlfn.CHOOSECOLS(_xlpm.row,_xlfn.SEQUENCE(,_xlpm.n,2,2)),_xlpm.mp,IFERROR(MIN(_xlfn._xlws.FILTER(_xlpm.p,_xlpm.p<>"")),""),IF(_xlpm.mp="","",INDEX(_xlpm.q,_xlfn.XMATCH(_xlpm.mp,_xlpm.p,0,-1))))} -> 8 | J19: =IF(D19=H19,"历史最低","") | K19: =(D19-H19)/H19 -> 0.77631579 | L19: =(E19-I19)/I19 -> -0.75 | M19: =IFERROR(L19/K19,"") -> -0.96610169 | N19: =IF(M19="","",IF(M19>0,"只卖不买",IF(M19>-0.3,"只卖不买",IF(M19>=-1.5,"交易区",IF(M19>=-2.5,"谨慎","危险盘"))))) -> 交易区 | O19: =(D19-F19)/F19 -> 0 | P19: =(E19-G19)/G19 -> -0.33333333 | Q19: =IFERROR(P19/O19,"") | R19: =IF(Q19="","",IF(Q19>0,"只卖不买",IF(Q19>-0.3,"只卖不买",IF(Q19>=-1.5,"交易区",IF(Q19>=-2.5,"谨慎","危险盘"))))) | S19: =IF(AND(N19="交易区",R19="交易区"),"双绿","") | T19: {=_xlfn.LET(_xlpm.key,$B19&"|"&$C19,_xlpm.kdb,价格数据库!$A$3:$A$2000&"|"&价格数据库!$B$3:$B$2000,_xlpm.r,_xlfn.XMATCH(_xlpm.key,_xlpm.kdb,0),_xlpm.row,INDEX(价格数据库!$C$3:$ZZ$2000,_xlpm.r,0),_xlpm.n,INT(COLUMNS(_xlpm.row)/2),_xlpm.p,_xlfn.CHOOSECOLS(_xlpm.row,_xlfn.SEQUENCE(,_xlpm.n,1,2)),IFERROR(MAX(_xlfn._xlws.FILTER(_xlpm.p,_xlpm.p<>"")),""))} -> 27000 | U19: {=_xlfn.LET(_xlpm.key,$B19&"|"&$C19,_xlpm.kdb,价格数据库!$A$3:$A$2000&"|"&价格数据库!$B$3:$B$2000,_xlpm.r,_xlfn.XMATCH(_xlpm.key,_xlpm.kdb,0),_xlpm.row,INDEX(价格数据库!$C$3:$ZZ$2000,_xlpm.r,0),_xlpm.n,INT(COLUMNS(_xlpm.row)/2),_xlpm.p,_xlfn.CHOOSECOLS(_xlpm.row,_xlfn.SEQUENCE(,_xlpm.n,1,2)),_xlpm.q,_xlfn.CHOOSECOLS(_xlpm.row,_xlfn.SEQUENCE(,_xlpm.n,2,2)),_xlpm.mx,IFERROR(MAX(_xlfn._xlws.FILTER(_xlpm.p,_xlpm.p<>"")),""),IF(_xlpm.mx="","",INDEX(_xlpm.q,_xlfn.XMATCH(_xlpm.mx,_xlpm.p,0,-1))))} -> 2
